Workbook

Sheet README
A1: Example dataset 1 – Bacterial occurrence and abundance (snapshot survey)
A2: SIMULATED DATA – for demonstrating the Biodiversity Forecasting Decision Framework app only. Water bodies and site codes are fictional; counts and measurements were generated by a statistical model and do not describe any real lake or river.
A4: What this is
A5: A genus-level bacterial abundance table from a single summer survey: 131 sites in 35 fictional water bodies, 329 freshwater bacterial genera. Values are sequence read counts per site (one 16S metabarcoding sample per site). Most genera are absent from most sites, as in real eDNA tables.
A6: Sheets
A7: abundance – read counts: one row per site, one column per genus. This is the table you would analyse.
A8: occurrence – presence (1) / absence (0), calculated from the abundance sheet with formulas.
A9: site_info – water body, type, region, habitat, sampling date, total reads and number of genera per site (formulas).
A10: genera – each genus, its broad taxonomic group and the number of sites where it was detected (formula).
A11: app_inputs – the values to type into the app for this dataset, calculated from the data where possible.
A12: How to use it
A13: Follow the worked example in occurrence_abundance.md in the GitHub repository. It shows how each app input is read from this workbook and what the app recommends.

Sheet abundance
A1: Site | B1: Limnohabitans | C1: Polynucleobacter | D1: Rhodoferax | E1: Albidiferax | F1: Curvibacter | G1: Hydrogenophaga | H1: Acidovorax | I1: Comamonas | J1: Delftia | K1: Methylibium | L1: Leptothrix | M1: Sphaerotilus | N1: Aquabacterium | O1: Rubrivivax | P1: Roseateles | Q1: Pelomonas | R1: Aquincola | S1: Inhella | T1: Malikia | U1: Simplicispira | V1: Diaphorobacter | W1: Alicycliphilus | X1: Brachymonas | Y1: Giesbergeria | Z1: Rhizobacter | AA1: Piscinibacter | AB1: Thiomonas | AC1: Ramlibacter | AD1: Caenimonas | AE1: Xenophilus | AF1: Herbaspirillum | AG1: Janthinobacterium | AH1: Undibacterium | AI1: Herminiimonas | AJ1: Oxalobacter | AK1: Ralstonia | AL1: Cupriavidus | AM1: Paraburkholderia | AN1: Achromobacter | AO1: Alcaligenes | AP1: Bordetella | AQ1: Methylotenera | AR1: Methylobacillus | AS1: Methylovorus | AT1: Nitrosomonas | AU1: Nitrosospira | AV1: Thiobacillus | AW1: Sulfuricella | AX1: Gallionella | AY1: Sideroxydans | AZ1: Dechloromonas | BA1: Zoogloea | BB1: Denitratisoma | BC1: Sterolibacterium | BD1: Ferribacterium | BE1: Propionivibrio | BF1: Uliginosibacterium | BG1: Rhodocyclus | BH1: Azonexus | BI1: Methyloversatilis | BJ1: Georgfuchsia | BK1: Candidatus Accumulibacter | BL1: Candidatus Methylopumilus | BM1: Hydrogenophilus | BN1: Candidatus Fonsibacter | BO1: Novosphingobium | BP1: Sphingomonas | BQ1: Sphingobium | BR1: Sphingopyxis | BS1: Sphingorhabdus | BT1: Blastomonas | BU1: Sandarakinorhabdus | BV1: Erythrobacter | BW1: Porphyrobacter | BX1: Altererythrobacter | BY1: Caulobacter | BZ1: Brevundimonas | CA1: Phenylobacterium | CB1: Asticcacaulis | CC1: Methylobacterium | CD1: Bradyrhizobium | CE1: Rhizobium | CF1: Mesorhizobium | CG1: Agrobacterium | CH1: Shinella | CI1: Devosia | CJ1: Afipia | CK1: Rhodopseudomonas | CL1: Rhodoplanes | CM1: Pedomicrobium | CN1: Hyphomonas | CO1: Rhodobacter | CP1: Paracoccus | CQ1: Gemmobacter | CR1: Rhodobaca | CS1: Tabrizicola | CT1: Roseomonas | CU1: Acidiphilium | CV1: Methylocystis | CW1: Methylosinus | CX1: Ochrobactrum | CY1: Reyranella | CZ1: Bauldia | DA1: Rhodomicrobium | DB1: Elstera | DC1: Rhodovarius | DD1: Pseudomonas | DE1: Acinetobacter | DF1: Aeromonas | DG1: Shewanella | DH1: Rheinheimera | DI1: Stenotrophomonas | DJ1: Lysobacter | DK1: Arenimonas | DL1: Luteimonas | DM1: Pseudoxanthomonas | DN1: Xanthomonas | DO1: Rhodanobacter | DP1: Dyella | DQ1: Legionella | DR1: Methylobacter | DS1: Crenothrix | DT1: Methylocaldum | DU1: Methylosarcina | DV1: Methylovulum | DW1: Methylomicrobium | DX1: Methyloglobulus | DY1: Beggiatoa | DZ1: Thioploca | EA1: Psychrobacter | EB1: Perlucidibaca | EC1: Cellvibrio | ED1: Serratia | EE1: Rahnella | EF1: Pantoea | EG1: Klebsiella | EH1: Escherichia | EI1: Hafnia | EJ1: Nevskia | EK1: Hydrocarboniphaga | EL1: Aquicella | EM1: Alishewanella | EN1: Tolumonas | EO1: Steroidobacter | EP1: Desulfovibrio | EQ1: Desulfomicrobium | ER1: Desulfobulbus | ES1: Desulfobacca | ET1: Desulfobacterium | EU1: Desulfatirhabdium | EV1: Geobacter | EW1: Syntrophus | EX1: Syntrophobacter | EY1: Smithella | EZ1: Syntrophorhabdus | FA1: Bdellovibrio | FB1: Haliangium | FC1: Anaeromyxobacter | FD1: Myxococcus | FE1: Sorangium | FF1: Nannocystis | FG1: Polyangium | FH1: Arcobacter | FI1: Sulfurospirillum | FJ1: Sulfuricurvum | FK1: Sulfurimonas | FL1: Candidatus Planktophila | FM1: Candidatus Nanopelagicus | FN1: Rhodoluna | FO1: Aurantimicrobium | FP1: Ilumatobacter | FQ1: Iamia | FR1: Microbacterium | FS1: Agromyces | FT1: Frigoribacterium | FU1: Mycobacterium | FV1: Arthrobacter | FW1: Aeromicrobium | FX1: Marmoricola | FY1: Streptomyces | FZ1: Micrococcus | GA1: Kocuria | GB1: Rothia | GC1: Rhodococcus | GD1: Gordonia | GE1: Nocardia | GF1: Dietzia | GG1: Pseudonocardia | GH1: Amycolatopsis | GI1: Actinoplanes | GJ1: Micromonospora | GK1: Blastococcus | GL1: Geodermatophilus | GM1: Modestobacter | GN1: Frankia | GO1: Demequina | GP1: Phycicoccus | GQ1: Tetrasphaera | GR1: Janibacter | GS1: Knoellia | GT1: Conexibacter | GU1: Candidatus Microthrix | GV1: Flavobacterium | GW1: Cloacibacterium | GX1: Fluviicola | GY1: Flectobacillus | GZ1: Runella | HA1: Spirosoma | HB1: Dyadobacter | HC1: Cytophaga | HD1: Sediminibacterium | HE1: Ferruginibacter | HF1: Terrimonas | HG1: Chitinophaga | HH1: Niabella | HI1: Lacibacter | HJ1: Haliscomenobacter | HK1: Solitalea | HL1: Mucilaginibacter | HM1: Sphingobacterium | HN1: Bacteroides | HO1: Prevotella | HP1: Lentimicrobium | HQ1: Rhodonellum | HR1: Lutibacter | HS1: Aquirufa | HT1: Fibrella | HU1: Flavisolibacter | HV1: Parasediminibacterium | HW1: Microcystis | HX1: Planktothrix | HY1: Dolichospermum | HZ1: Aphanizomenon | IA1: Synechococcus | IB1: Cyanobium | IC1: Pseudanabaena | ID1: Raphidiopsis | IE1: Nostoc | IF1: Anabaena | IG1: Oscillatoria | IH1: Phormidium | II1: Snowella | IJ1: Woronichinia | IK1: Limnothrix | IL1: Planktolyngbya | IM1: Chroococcus | IN1: Aphanocapsa | IO1: Merismopedia | IP1: Tychonema | IQ1: Microseira | IR1: Luteolibacter | IS1: Prosthecobacter | IT1: Verrucomicrobium | IU1: Opitutus | IV1: Lacunisphaera | IW1: Roseimicrobium | IX1: Brevifollis | IY1: Persicirhabdus | IZ1: Terrimicrobium | JA1: Candidatus Udaeobacter | JB1: Chthoniobacter | JC1: Planctomyces | JD1: Gemmata | JE1: Pirellula | JF1: Rhodopirellula | JG1: Schlesneria | JH1: Zavarzinella | JI1: Blastopirellula | JJ1: Planctopirus | JK1: Tepidisphaera | JL1: Acidobacterium | JM1: Granulicella | JN1: Bryobacter | JO1: Candidatus Solibacter | JP1: Geothrix | JQ1: Terriglobus | JR1: Edaphobacter | JS1: Luteitalea | JT1: Vicinamibacter | JU1: Chloroflexus | JV1: Anaerolinea | JW1: Longilinea | JX1: Bellilinea | JY1: Levilinea | JZ1: Roseiflexus | KA1: Herpetosiphon | KB1: Caldilinea | KC1: Leptolinea | KD1: Ornatilinea | KE1: Litorilinea | KF1: Bacillus | KG1: Paenibacillus | KH1: Lysinibacillus | KI1: Brevibacillus | KJ1: Exiguobacterium | KK1: Planococcus | KL1: Staphylococcus | KM1: Clostridium | KN1: Turicibacter | KO1: Sporomusa | KP1: Acetobacterium | KQ1: Desulfitobacterium | KR1: Desulfosporosinus | KS1: Carnobacterium | KT1: Lactococcus | KU1: Streptococcus | KV1: Enterococcus | KW1: Faecalibacterium | KX1: Blautia | KY1: Ruminococcus | KZ1: Dorea | LA1: Lachnoclostridium | LB1: Subdoligranulum | LC1: Sedimentibacter | LD1: Christensenella | LE1: Nitrospira | LF1: Thermodesulfovibrio | LG1: Gemmatimonas | LH1: Armatimonas | LI1: Fimbriimonas | LJ1: Deinococcus | LK1: Leptospira | LL1: Treponema | LM1: Ignavibacterium | LN1: Chlorobium | LO1: Pelodictyon | LP1: Fusobacterium | LQ1: Elusimicrobium | LR1: Fibrobacter
A2: NW-ASHME-LIT01 | B2: 26 | C2: 0 | D2: 9 | E2: 25 | F2: 0 | G2: 0 | H2: 0 | I2: 0 | J2: 17 | K2: 1 | L2: 0 | M2: 0 | N2: 0 | O2: 0 | P2: 0 | Q2: 0 | R2: 0 | S2: 0 | T2: 0 | U2: 0 | V2: 0 | W2: 0 | X2: 0 | Y2: 8 | Z2: 0 | AA2: 0 | AB2: 31 | AC2: 0 | AD2: 0 | AE2: 0 | AF2: 2 | AG2: 0 | AH2: 0 | AI2: 0 | AJ2: 2 | AK2: 2 | AL2: 2 | AM2: 0 | AN2: 0 | AO2: 0 | AP2: 0 | AQ2: 0 | AR2: 0 | AS2: 0 | AT2: 0 | AU2: 8 | AV2: 0 | AW2: 0 | AX2: 0 | AY2: 0 | AZ2: 0 | BA2: 1 | BB2: 0 | BC2: 2 | BD2: 0 | BE2: 0 | BF2: 0 | BG2: 0 | BH2: 0 | BI2: 0 | BJ2: 0 | BK2: 2 | BL2: 0 | BM2: 0 | BN2: 0 | BO2: 0 | BP2: 0 | BQ2: 0 | BR2: 0 | BS2: 0 | BT2: 0 | BU2: 0 | BV2: 2 | BW2: 0 | BX2: 0 | BY2: 0 | BZ2: 0 | CA2: 0 | CB2: 0 | CC2: 8 | CD2: 194 | CE2: 0 | CF2: 0 | CG2: 0 | CH2: 0 | CI2: 0 | CJ2: 0 | CK2: 0 | CL2: 4 | CM2: 0 | CN2: 0 | CO2: 0 | CP2: 64 | CQ2: 1 | CR2: 0 | CS2: 0 | CT2: 0 | CU2: 0 | CV2: 11 | CW2: 0 | CX2: 103 | CY2: 35 | CZ2: 15 | DA2: 0 | DB2: 0 | DC2: 0 | DD2: 0 | DE2: 8 | DF2: 0 | DG2: 0 | DH2: 0 | DI2: 0 | DJ2: 0 | DK2: 0 | DL2: 0 | DM2: 1 | DN2: 0 | DO2: 2 | DP2: 0 | DQ2: 1300 | DR2: 2 | DS2: 0 | DT2: 0 | DU2: 1 | DV2: 0 | DW2: 36 | DX2: 0 | DY2: 0 | DZ2: 17 | EA2: 0 | EB2: 65 | EC2: 81 | ED2: 0 | EE2: 0 | EF2: 0 | EG2: 0 | EH2: 0 | EI2: 0 | EJ2: 0 | EK2: 650 | EL2: 0 | EM2: 0 | EN2: 1 | EO2: 0 | EP2: 0 | EQ2: 33 | ER2: 0 | ES2: 0 | ET2: 0 | EU2: 2 | EV2: 1 | EW2: 0 | EX2: 0 | EY2: 0 | EZ2: 0 | FA2: 0 | FB2: 0 | FC2: 9 | FD2: 0 | FE2: 8 | FF2: 0 | FG2: 0 | FH2: 0 | FI2: 0 | FJ2: 11 | FK2: 0 | FL2: 36672 | FM2: 0 | FN2: 0 | FO2: 0 | FP2: 0 | FQ2: 15 | FR2: 1 | FS2: 0 | FT2: 0 | FU2: 0 | FV2: 0 | FW2: 0 | FX2: 1 | FY2: 0 | FZ2: 0 | GA2: 0 | GB2: 0 | GC2: 0 | GD2: 0 | GE2: 3 | GF2: 5 | GG2: 0 | GH2: 0 | GI2: 0 | GJ2: 4 | GK2: 0 | GL2: 0 | GM2: 0 | GN2: 0 | GO2: 5 | GP2: 0 | GQ2: 6 | GR2: 0 | GS2: 0 | GT2: 0 | GU2: 0 | GV2: 0 | GW2: 0 | GX2: 0 | GY2: 16 | GZ2: 0 | HA2: 826 | HB2: 1643 | HC2: 0 | HD2: 0 | HE2: 0 | HF2: 0 | HG2: 2 | HH2: 0 | HI2: 10 | HJ2: 0 | HK2: 0 | HL2: 0 | HM2: 0 | HN2: 0 | HO2: 1 | HP2: 0 | HQ2: 0 | HR2: 0 | HS2: 0 | HT2: 0 | HU2: 0 | HV2: 0 | HW2: 0 | HX2: 0 | HY2: 4217 | HZ2: 2 | IA2: 88 | IB2: 2439 | IC2: 0 | ID2: 0 | IE2: 30 | IF2: 3 | IG2: 1 | IH2: 35 | II2: 0 | IJ2: 1 | IK2: 0 | IL2: 0 | IM2: 0 | IN2: 1 | IO2: 0 | IP2: 7 | IQ2: 0 | IR2: 2 | IS2: 0 | IT2: 0 | IU2: 0 | IV2: 0 | IW2: 1 | IX2: 182 | IY2: 0 | IZ2: 0 | JA2: 29 | JB2: 0 | JC2: 0 | JD2: 1 | JE2: 2 | JF2: 8 | JG2: 5 | JH2: 0 | JI2: 0 | JJ2: 0 | JK2: 0 | JL2: 0 | JM2: 0 | JN2: 0 | JO2: 14 | JP2: 0 | JQ2: 0 | JR2: 0 | JS2: 88 | JT2: 0 | JU2: 0 | JV2: 0 | JW2: 0 | JX2: 2 | JY2: 0 | JZ2: 0 | KA2: 0 | KB2: 0 | KC2: 0 | KD2: 0 | KE2: 0 | KF2: 1 | KG2: 67 | KH2: 0 | KI2: 8 | KJ2: 0 | KK2: 0 | KL2: 0 | KM2: 0 | KN2: 0 | KO2: 0 | KP2: 0 | KQ2: 2 | KR2: 0 | KS2: 0 | KT2: 1 | KU2: 0 | KV2: 0 | KW2: 0 | KX2: 0 | KY2: 0 | KZ2: 0 | LA2: 0 | LB2: 0 | LC2: 0 | LD2: 1 | LE2: 0 | LF2: 0 | LG2: 1 | LH2: 4 | LI2: 0 | LJ2: 93 | LK2: 0 | LL2: 0 | LM2: 0 | LN2: 0 | LO2: 0 | LP2: 0 | LQ2: 21 | LR2: 0
A3: NW-ASHME-PEL02 | B3: 0 | C3: 0 | D3: 5 | E3: 0 | F3: 0 | G3: 0 | H3: 0 | I3: 0 | J3: 1 | K3: 0 | L3: 0 | M3: 0 | N3: 0 | O3: 0 | P3: 0 | Q3: 0 | R3: 0 | S3: 0 | T3: 0 | U3: 0 | V3: 0 | W3: 0 | X3: 0 | Y3: 29 | Z3: 0 | AA3: 1 | AB3: 16 | AC3: 0 | AD3: 0 | AE3: 0 | AF3: 0 | AG3: 0 | AH3: 0 | AI3: 0 | AJ3: 48 | AK3: 12 | AL3: 0 | AM3: 0 | AN3: 0 | AO3: 40 | AP3: 0 | AQ3: 0 | AR3: 11 | AS3: 0 | AT3: 18 | AU3: 4 | AV3: 0 | AW3: 0 | AX3: 0 | AY3: 0 | AZ3: 0 | BA3: 0 | BB3: 3 | BC3: 0 | BD3: 0 | BE3: 1 | BF3: 0 | BG3: 0 | BH3: 0 | BI3: 2 | BJ3: 0 | BK3: 5 | BL3: 0 | BM3: 0 | BN3: 0 | BO3: 1 | BP3: 2 | BQ3: 0 | BR3: 0 | BS3: 0 | BT3: 0 | BU3: 1 | BV3: 1 | BW3: 0 | BX3: 0 | BY3: 0 | BZ3: 0 | CA3: 0 | CB3: 0 | CC3: 2 | CD3: 242 | CE3: 0 | CF3: 0 | CG3: 0 | CH3: 0 | CI3: 0 | CJ3: 1 | CK3: 0 | CL3: 2 | CM3: 0 | CN3: 0 | CO3: 0 | CP3: 0 | CQ3: 0 | CR3: 3 | CS3: 0 | CT3: 0 | CU3: 0 | CV3: 4 | CW3: 0 | CX3: 0 | CY3: 19 | CZ3: 30 | DA3: 1 | DB3: 0 | DC3: 0 | DD3: 0 | DE3: 1 | DF3: 0 | DG3: 0 | DH3: 16 | DI3: 0 | DJ3: 0 | DK3: 0 | DL3: 1043 | DM3: 5 | DN3: 0 | DO3: 0 | DP3: 0 | DQ3: 6 | DR3: 0 | DS3: 0 | DT3: 0 | DU3: 6 | DV3: 0 | DW3: 93 | DX3: 0 | DY3: 0 | DZ3: 2 | EA3: 0 | EB3: 14 | EC3: 2 | ED3: 0 | EE3: 0 | EF3: 13 | EG3: 0 | EH3: 0 | EI3: 0 | EJ3: 0 | EK3: 14 | EL3: 24 | EM3: 0 | EN3: 0 | EO3: 9 | EP3: 0 | EQ3: 33 | ER3: 0 | ES3: 0 | ET3: 0 | EU3: 1 | EV3: 0 | EW3: 0 | EX3: 0 | EY3: 0 | EZ3: 0 | FA3: 0 | FB3: 0 | FC3: 0 | FD3: 0 | FE3: 587 | FF3: 4 | FG3: 0 | FH3: 0 | FI3: 0 | FJ3: 2 | FK3: 0 | FL3: 59670 | FM3: 1 | FN3: 0 | FO3: 0 | FP3: 0 | FQ3: 16 | FR3: 26 | FS3: 1 | FT3: 0 | FU3: 0 | FV3: 4 | FW3: 0 | FX3: 0 | FY3: 0 | FZ3: 0 | GA3: 0 | GB3: 0 | GC3: 0 | GD3: 0 | GE3: 6 | GF3: 1 | GG3: 0 | GH3: 0 | GI3: 0 | GJ3: 0 | GK3: 0 | GL3: 0 | GM3: 0 | GN3: 0 | GO3: 12 | GP3: 0 | GQ3: 0 | GR3: 0 | GS3: 49 | GT3: 13 | GU3: 0 | GV3: 594 | GW3: 1 | GX3: 0 | GY3: 1 | GZ3: 0 | HA3: 35 | HB3: 0 | HC3: 0 | HD3: 0 | HE3: 0 | HF3: 0 | HG3: 77 | HH3: 0 | HI3: 290 | HJ3: 0 | HK3: 0 | HL3: 2 | HM3: 0 | HN3: 0 | HO3: 8 | HP3: 0 | HQ3: 0 | HR3: 0 | HS3: 0 | HT3: 0 | HU3: 0 | HV3: 0 | HW3: 2093 | HX3: 34066 | HY3: 107 | HZ3: 1 | IA3: 69 | IB3: 6 | IC3: 0 | ID3: 0 | IE3: 3 | IF3: 12 | IG3: 0 | IH3: 4 | II3: 0 | IJ3: 2 | IK3: 0 | IL3: 28 | IM3: 1737 | IN3: 0 | IO3: 0 | IP3: 1 | IQ3: 40 | IR3: 12 | IS3: 0 | IT3: 0 | IU3: 6 | IV3: 3 | IW3: 8 | IX3: 0 | IY3: 0 | IZ3: 0 | JA3: 0 | JB3: 0 | JC3: 0 | JD3: 8 | JE3: 1 | JF3: 0 | JG3: 231 | JH3: 0 | JI3: 0 | JJ3: 0 | JK3: 0 | JL3: 0 | JM3: 0 | JN3: 0 | JO3: 0 | JP3: 0 | JQ3: 0 | JR3: 0 | JS3: 102 | JT3: 0 | JU3: 0 | JV3: 0 | JW3: 0 | JX3: 0 | JY3: 0 | JZ3: 0 | KA3: 0 | KB3: 0 | KC3: 1 | KD3: 0 | KE3: 2 | KF3: 0 | KG3: 9 | KH3: 0 | KI3: 0 | KJ3: 0 | KK3: 0 | KL3: 0 | KM3: 0 | KN3: 0 | KO3: 0 | KP3: 0 | KQ3: 37 | KR3: 0 | KS3: 0 | KT3: 0 | KU3: 0 | KV3: 0 | KW3: 0 | KX3: 1 | KY3: 0 | KZ3: 11 | LA3: 0 | LB3: 0 | LC3: 0 | LD3: 0 | LE3: 0 | LF3: 0 | LG3: 24 | LH3: 0 | LI3: 0 | LJ3: 7 | LK3: 0 | LL3: 0 | LM3: 0 | LN3: 0 | LO3: 0 | LP3: 10 | LQ3: 12 | LR3: 0
A4: NW-ASHME-OUT03 | B4: 3 | C4: 0 | D4: 1659 | E4: 132 | F4: 0 | G4: 0 | H4: 1 | I4: 0 | J4: 3 | K4: 57 | L4: 0 | M4: 0 | N4: 0 | O4: 9 | P4: 0 | Q4: 1 | R4: 0 | S4: 0 | T4: 0 | U4: 12 | V4: 0 | W4: 0 | X4: 0 | Y4: 0 | Z4: 0 | AA4: 1 | AB4: 21 | AC4: 0 | AD4: 0 | AE4: 0 | AF4: 0 | AG4: 0 | AH4: 33 | AI4: 0 | AJ4: 7 | AK4: 0 | AL4: 10 | AM4: 28 | AN4: 9 | AO4: 0 | AP4: 0 | AQ4: 0 | AR4: 0 | AS4: 0 | AT4: 2 | AU4: 234 | AV4: 0 | AW4: 0 | AX4: 0 | AY4: 0 | AZ4: 0 | BA4: 0 | BB4: 0 | BC4: 0 | BD4: 11 | BE4: 13 | BF4: 0 | BG4: 0 | BH4: 0 | BI4: 11 | BJ4: 0 | BK4: 2 | BL4: 0 | BM4: 26 | BN4: 0 | BO4: 26 | BP4: 0 | BQ4: 0 | BR4: 0 | BS4: 0 | BT4: 0 | BU4: 1 | BV4: 1 | BW4: 0 | BX4: 0 | BY4: 0 | BZ4: 0 | CA4: 14 | CB4: 0 | CC4: 7 | CD4: 71 | CE4: 0 | CF4: 0 | CG4: 0 | CH4: 0 | CI4: 0 | CJ4: 0 | CK4: 138 | CL4: 0 | CM4: 0 | CN4: 0 | CO4: 0 | CP4: 0 | CQ4: 0 | CR4: 15 | CS4: 0 | CT4: 0 | CU4: 1 | CV4: 0 | CW4: 0 | CX4: 1 | CY4: 101 | CZ4: 1 | DA4: 0 | DB4: 0 | DC4: 0 | DD4: 1 | DE4: 14 | DF4: 0 | DG4: 0 | DH4: 2 | DI4: 0 | DJ4: 6 | DK4: 0 | DL4: 30 | DM4: 787 | DN4: 0 | DO4: 5 | DP4: 0 | DQ4: 7 | DR4: 0 | DS4: 4 | DT4: 0 | DU4: 2 | DV4: 0 | DW4: 0 | DX4: 0 | DY4: 0 | DZ4: 120 | EA4: 0 | EB4: 7 | EC4: 0 | ED4: 0 | EE4: 0 | EF4: 0 | EG4: 0 | EH4: 0 | EI4: 0 | EJ4: 0 | EK4: 37 | EL4: 0 | EM4: 0 | EN4: 0 | EO4: 0 | EP4: 0 | EQ4: 1 | ER4: 0 | ES4: 0 | ET4: 0 | EU4: 71 | EV4: 0 | EW4: 0 | EX4: 0 | EY4: 0 | EZ4: 0 | FA4: 3 | FB4: 8 | FC4: 0 | FD4: 0 | FE4: 0 | FF4: 0 | FG4: 0 | FH4: 0 | FI4: 41 | FJ4: 0 | FK4: 0 | FL4: 219 | FM4: 0 | FN4: 0 | FO4: 0 | FP4: 0 | FQ4: 1 | FR4: 25 | FS4: 11 | FT4: 0 | FU4: 0 | FV4: 2 | FW4: 0 | FX4: 44 | FY4: 0 | FZ4: 0 | GA4: 0 | GB4: 0 | GC4: 0 | GD4: 0 | GE4: 175 | GF4: 157 | GG4: 0 | GH4: 0 | GI4: 0 | GJ4: 0 | GK4: 0 | GL4: 0 | GM4: 0 | GN4: 0 | GO4: 3 | GP4: 0 | GQ4: 0 | GR4: 0 | GS4: 2 | GT4: 0 | GU4: 23 | GV4: 0 | GW4: 0 | GX4: 0 | GY4: 0 | GZ4: 0 | HA4: 3 | HB4: 0 | HC4: 0 | HD4: 0 | HE4: 0 | HF4: 7 | HG4: 26 | HH4: 0 | HI4: 0 | HJ4: 0 | HK4: 0 | HL4: 0 | HM4: 0 | HN4: 0 | HO4: 0 | HP4: 0 | HQ4: 8 | HR4: 0 | HS4: 0 | HT4: 0 | HU4: 1 | HV4: 0 | HW4: 5378 | HX4: 4357 | HY4: 645 | HZ4: 0 | IA4: 1 | IB4: 9806 | IC4: 0 | ID4: 0 | IE4: 0 | IF4: 2 | IG4: 1 | IH4: 39 | II4: 0 | IJ4: 0 | IK4: 0 | IL4: 1 | IM4: 48 | IN4: 121 | IO4: 0 | IP4: 0 | IQ4: 153 | IR4: 19 | IS4: 2 | IT4: 0 | IU4: 0 | IV4: 267 | IW4: 31 | IX4: 0 | IY4: 0 | IZ4: 5 | JA4: 0 | JB4: 3 | JC4: 0 | JD4: 35 | JE4: 0 | JF4: 1 | JG4: 2 | JH4: 0 | JI4: 0 | JJ4: 0 | JK4: 6 | JL4: 0 | JM4: 0 | JN4: 0 | JO4: 107 | JP4: 0 | JQ4: 1 | JR4: 0 | JS4: 2 | JT4: 1 | JU4: 4 | JV4: 0 | JW4: 0 | JX4: 2 | JY4: 0 | JZ4: 15 | KA4: 0 | KB4: 0 | KC4: 0 | KD4: 0 | KE4: 1 | KF4: 0 | KG4: 323 | KH4: 34 | KI4: 2 | KJ4: 0 | KK4: 0 | KL4: 0 | KM4: 0 | KN4: 3 | KO4: 0 | KP4: 2 | KQ4: 37 | KR4: 0 | KS4: 0 | KT4: 7 | KU4: 0 | KV4: 0 | KW4: 0 | KX4: 1 | KY4: 1 | KZ4: 1 | LA4: 0 | LB4: 0 | LC4: 19 | LD4: 0 | LE4: 0 | LF4: 0 | LG4: 0 | LH4: 0 | LI4: 0 | LJ4: 0 | LK4: 29 | LL4: 0 | LM4: 0 | LN4: 11 | LO4: 0 | LP4: 20 | LQ4: 44 | LR4: 0
A5: NW-ASHME-SED04 | B5: 0 | C5: 0 | D5: 39 | E5: 10 | F5: 0 | G5: 0 | H5: 86 | I5: 0 | J5: 0 | K5: 0 | L5: 9 | M5: 0 | N5: 0 | O5: 0 | P5: 0 | Q5: 0 | R5: 0 | S5: 0 | T5: 0 | U5: 0 | V5: 0 | W5: 3 | X5: 0 | Y5: 0 | Z5: 0 | AA5: 0 | AB5: 6 | AC5: 0 | AD5: 1 | AE5: 0 | AF5: 5 | AG5: 0 | AH5: 0 | AI5: 0 | AJ5: 8 | AK5: 0 | AL5: 0 | AM5: 0 | AN5: 561 | AO5: 348 | AP5: 0 | AQ5: 0 | AR5: 357 | AS5: 0 | AT5: 7 | AU5: 0 | AV5: 306 | AW5: 0 | AX5: 0 | AY5: 0 | AZ5: 0 | BA5: 0 | BB5: 171 | BC5: 0 | BD5: 0 | BE5: 3 | BF5: 0 | BG5: 0 | BH5: 0 | BI5: 182 | BJ5: 0 | BK5: 0 | BL5: 0 | BM5: 1467 | BN5: 0 | BO5: 2122 | BP5: 19 | BQ5: 0 | BR5: 0 | BS5: 0 | BT5: 0 | BU5: 0 | BV5: 0 | BW5: 0 | BX5: 0 | BY5: 0 | BZ5: 0 | CA5: 0 | CB5: 0 | CC5: 0 | CD5: 14 | CE5: 3 | CF5: 2 | CG5: 0 | CH5: 0 | CI5: 0 | CJ5: 0 | CK5: 33 | CL5: 1 | CM5: 0 | CN5: 0 | CO5: 0 | CP5: 0 | CQ5: 3 | CR5: 0 | CS5: 0 | CT5: 94 | CU5: 0 | CV5: 36 | CW5: 0 | CX5: 0 | CY5: 38 | CZ5: 6 | DA5: 0 | DB5: 0 | DC5: 0 | DD5: 3 | DE5: 2 | DF5: 0 | DG5: 0 | DH5: 150 | DI5: 0 | DJ5: 6 | DK5: 0 | DL5: 0 | DM5: 3 | DN5: 0 | DO5: 0 | DP5: 0 | DQ5: 0 | DR5: 1 | DS5: 2 | DT5: 0 | DU5: 2 | DV5: 0 | DW5: 408 | DX5: 0 | DY5: 0 | DZ5: 19 | EA5: 0 | EB5: 3 | EC5: 27 | ED5: 0 | EE5: 0 | EF5: 0 | EG5: 0 | EH5: 0 | EI5: 0 | EJ5: 0 | EK5: 25 | EL5: 28 | EM5: 0 | EN5: 4 | EO5: 32 | EP5: 0 | EQ5: 36 | ER5: 0 | ES5: 15 | ET5: 0 | EU5: 227 | EV5: 998 | EW5: 1 | EX5: 0 | EY5: 0 | EZ5: 0 | FA5: 0 | FB5: 4 | FC5: 0 | FD5: 0 | FE5: 1 | FF5: 8 | FG5: 0 | FH5: 0 | FI5: 1 | FJ5: 0 | FK5: 0 | FL5: 0 | FM5: 0 | FN5: 0 | FO5: 0 | FP5: 0 | FQ5: 0 | FR5: 28 | FS5: 12 | FT5: 0 | FU5: 0 | FV5: 0 | FW5: 0 | FX5: 14 | FY5: 0 | FZ5: 0 | GA5: 0 | GB5: 0 | GC5: 0 | GD5: 0 | GE5: 13 | GF5: 0 | GG5: 0 | GH5: 0 | GI5: 0 | GJ5: 0 | GK5: 0 | GL5: 0 | GM5: 0 | GN5: 0 | GO5: 0 | GP5: 0 | GQ5: 0 | GR5: 609 | GS5: 3 | GT5: 3 | GU5: 0 | GV5: 0 | GW5: 0 | GX5: 0 | GY5: 16 | GZ5: 0 | HA5: 257 | HB5: 4 | HC5: 0 | HD5: 0 | HE5: 0 | HF5: 0 | HG5: 2170 | HH5: 0 | HI5: 1 | HJ5: 0 | HK5: 11 | HL5: 102 | HM5: 0 | HN5: 0 | HO5: 0 | HP5: 0 | HQ5: 1 | HR5: 0 | HS5: 0 | HT5: 0 | HU5: 0 | HV5: 0 | HW5: 2451 | HX5: 63 | HY5: 437 | HZ5: 0 | IA5: 18 | IB5: 1 | IC5: 1 | ID5: 0 | IE5: 659 | IF5: 11 | IG5: 0 | IH5: 14 | II5: 0 | IJ5: 63 | IK5: 0 | IL5: 9 | IM5: 0 | IN5: 68 | IO5: 0 | IP5: 8 | IQ5: 3 | IR5: 64 | IS5: 0 | IT5: 0 | IU5: 2 | IV5: 52 | IW5: 0 | IX5: 18 | IY5: 0 | IZ5: 1 | JA5: 0 | JB5: 0 | JC5: 0 | JD5: 317 | JE5: 0 | JF5: 3 | JG5: 0 | JH5: 0 | JI5: 0 | JJ5: 7 | JK5: 0 | JL5: 0 | JM5: 0 | JN5: 0 | JO5: 2 | JP5: 3 | JQ5: 0 | JR5: 0 | JS5: 51 | JT5: 0 | JU5: 0 | JV5: 0 | JW5: 0 | JX5: 64 | JY5: 0 | JZ5: 0 | KA5: 0 | KB5: 0 | KC5: 3 | KD5: 0 | KE5: 7 | KF5: 0 | KG5: 0 | KH5: 2 | KI5: 0 | KJ5: 2 | KK5: 0 | KL5: 0 | KM5: 0 | KN5: 1 | KO5: 3 | KP5: 7 | KQ5: 7 | KR5: 0 | KS5: 0 | KT5: 0 | KU5: 0 | KV5: 0 | KW5: 0 | KX5: 3 | KY5: 0 | KZ5: 1 | LA5: 0 | LB5: 0 | LC5: 0 | LD5: 2 | LE5: 0 | LF5: 0 | LG5: 0 | LH5: 0 | LI5: 0 | LJ5: 0 | LK5: 0 | LL5: 0 | LM5: 0 | LN5: 11 | LO5: 0 | LP5: 0 | LQ5: 0 | LR5: 0
A6: NE-BRATA-LIT01 | B6: 59 | C6: 774 | D6: 0 | E6: 0 | F6: 0 | G6: 2 | H6: 0 | I6: 0 | J6: 1 | K6: 0 | L6: 0 | M6: 0 | N6: 1 | O6: 3 | P6: 924 | Q6: 0 | R6: 42 | S6: 0 | T6: 0 | U6: 0 | V6: 1 | W6: 0 | X6: 0 | Y6: 0 | Z6: 0 | AA6: 3 | AB6: 0 | AC6: 0 | AD6: 28 | AE6: 0 | AF6: 4 | AG6: 0 | AH6: 1 | AI6: 0 | AJ6: 0 | AK6: 0 | AL6: 8 | AM6: 0 | AN6: 2 | AO6: 1 | AP6: 0 | AQ6: 0 | AR6: 1 | AS6: 2 | AT6: 0 | AU6: 0 | AV6: 0 | AW6: 0 | AX6: 0 | AY6: 0 | AZ6: 0 | BA6: 0 | BB6: 0 | BC6: 0 | BD6: 0 | BE6: 0 | BF6: 0 | BG6: 7 | BH6: 0 | BI6: 0 | BJ6: 0 | BK6: 1 | BL6: 1 | BM6: 0 | BN6: 117 | BO6: 0 | BP6: 0 | BQ6: 0 | BR6: 35 | BS6: 5 | BT6: 22 | BU6: 2 | BV6: 0 | BW6: 0 | BX6: 0 | BY6: 421 | BZ6: 0 | CA6: 0 | CB6: 90 | CC6: 0 | CD6: 0 | CE6: 6 | CF6: 0 | CG6: 0 | CH6: 0 | CI6: 0 | CJ6: 0 | CK6: 0 | CL6: 301 | CM6: 0 | CN6: 0 | CO6: 3 | CP6: 0 | CQ6: 2 | CR6: 0 | CS6: 0 | CT6: 0 | CU6: 0 | CV6: 1 | CW6: 0 | CX6: 0 | CY6: 0 | CZ6: 0 | DA6: 1 | DB6: 48 | DC6: 0 | DD6: 1 | DE6: 3 | DF6: 0 | DG6: 4 | DH6: 0 | DI6: 3 | DJ6: 1 | DK6: 6 | DL6: 0 | DM6: 0 | DN6: 85 | DO6: 0 | DP6: 12 | DQ6: 0 | DR6: 0 | DS6: 0 | DT6: 0 | DU6: 0 | DV6: 0 | DW6: 0 | DX6: 19 | DY6: 0 | DZ6: 0 | EA6: 2 | EB6: 0 | EC6: 0 | ED6: 0 | EE6: 0 | EF6: 56 | EG6: 0 | EH6: 0 | EI6: 6 | EJ6: 1 | EK6: 0 | EL6: 0 | EM6: 0 | EN6: 0 | EO6: 6 | EP6: 20 | EQ6: 0 | ER6: 0 | ES6: 0 | ET6: 0 | EU6: 0 | EV6: 0 | EW6: 0 | EX6: 0 | EY6: 0 | EZ6: 0 | FA6: 0 | FB6: 0 | FC6: 9 | FD6: 0 | FE6: 0 | FF6: 0 | FG6: 18 | FH6: 0 | FI6: 0 | FJ6: 0 | FK6: 0 | FL6: 0 | FM6: 3399 | FN6: 0 | FO6: 0 | FP6: 2 | FQ6: 0 | FR6: 0 | FS6: 6 | FT6: 0 | FU6: 0 | FV6: 0 | FW6: 4 | FX6: 2 | FY6: 1 | FZ6: 0 | GA6: 0 | GB6: 1 | GC6: 1 | GD6: 0 | GE6: 0 | GF6: 0 | GG6: 0 | GH6: 0 | GI6: 49 | GJ6: 0 | GK6: 2 | GL6: 0 | GM6: 51 | GN6: 14 | GO6: 11 | GP6: 1 | GQ6: 3 | GR6: 0 | GS6: 0 | GT6: 0 | GU6: 0 | GV6: 0 | GW6: 0 | GX6: 14 | GY6: 0 | GZ6: 0 | HA6: 0 | HB6: 0 | HC6: 57 | HD6: 120 | HE6: 0 | HF6: 13 | HG6: 0 | HH6: 2 | HI6: 0 | HJ6: 3 | HK6: 0 | HL6: 0 | HM6: 0 | HN6: 0 | HO6: 0 | HP6: 0 | HQ6: 0 | HR6: 0 | HS6: 0 | HT6: 7 | HU6: 0 | HV6: 114 | HW6: 1 | HX6: 0 | HY6: 0 | HZ6: 0 | IA6: 271 | IB6: 148 | IC6: 9 | ID6: 0 | IE6: 0 | IF6: 0 | IG6: 0 | IH6: 0 | II6: 0 | IJ6: 0 | IK6: 0 | IL6: 0 | IM6: 72 | IN6: 0 | IO6: 0 | IP6: 0 | IQ6: 3 | IR6: 0 | IS6: 4 | IT6: 2 | IU6: 0 | IV6: 0 | IW6: 0 | IX6: 0 | IY6: 0 | IZ6: 0 | JA6: 0 | JB6: 0 | JC6: 0 | JD6: 0 | JE6: 0 | JF6: 1 | JG6: 0 | JH6: 0 | JI6: 0 | JJ6: 0 | JK6: 0 | JL6: 16 | JM6: 5 | JN6: 0 | JO6: 0 | JP6: 0 | JQ6: 0 | JR6: 0 | JS6: 0 | JT6: 0 | JU6: 0 | JV6: 0 | JW6: 17 | JX6: 0 | JY6: 0 | JZ6: 0 | KA6: 5 | KB6: 0 | KC6: 0 | KD6: 0 | KE6: 0 | KF6: 16 | KG6: 0 | KH6: 0 | KI6: 0 | KJ6: 38 | KK6: 6 | KL6: 0 | KM6: 18 | KN6: 0 | KO6: 0 | KP6: 0 | KQ6: 0 | KR6: 0 | KS6: 0 | KT6: 0 | KU6: 11 | KV6: 0 | KW6: 0 | KX6: 0 | KY6: 0 | KZ6: 0 | LA6: 0 | LB6: 0 | LC6: 0 | LD6: 2 | LE6: 64 | LF6: 0 | LG6: 0 | LH6: 0 | LI6: 0 | LJ6: 0 | LK6: 2 | LL6: 209 | LM6: 46 | LN6: 0 | LO6: 0 | LP6: 1 | LQ6: 0 | LR6: 0
A7: NE-BRATA-PEL02 | B7: 516 | C7: 12202 | D7: 0 | E7: 0 | F7: 0 | G7: 0 | H7: 2 | I7: 0 | J7: 0 | K7: 0 | L7: 0 | M7: 1 | N7: 0 | O7: 0 | P7: 1 | Q7: 0 | R7: 0 | S7: 7 | T7: 0 | U7: 0 | V7: 0 | W7: 2 | X7: 0 | Y7: 0 | Z7: 0 | AA7: 5 | AB7: 0 | AC7: 2 | AD7: 29 | AE7: 0 | AF7: 0 | AG7: 0 | AH7: 0 | AI7: 0 | AJ7: 0 | AK7: 0 | AL7: 0 | AM7: 0 | AN7: 0 | AO7: 0 | AP7: 0 | AQ7: 0 | AR7: 0 | AS7: 1 | AT7: 0 | AU7: 0 | AV7: 0 | AW7: 0 | AX7: 0 | AY7: 19 | AZ7: 0 | BA7: 0 | BB7: 0 | BC7: 0 | BD7: 0 | BE7: 0 | BF7: 0 | BG7: 1 | BH7: 0 | BI7: 0 | BJ7: 4 | BK7: 0 | BL7: 0 | BM7: 1 | BN7: 26408 | BO7: 0 | BP7: 0 | BQ7: 0 | BR7: 5 | BS7: 4 | BT7: 51 | BU7: 0 | BV7: 0 | BW7: 18 | BX7: 0 | BY7: 0 | BZ7: 0 | CA7: 0 | CB7: 4 | CC7: 0 | CD7: 0 | CE7: 0 | CF7: 0 | CG7: 8 | CH7: 0 | CI7: 0 | CJ7: 0 | CK7: 0 | CL7: 17 | CM7: 0 | CN7: 1 | CO7: 0 | CP7: 0 | CQ7: 2 | CR7: 0 | CS7: 4 | CT7: 0 | CU7: 0 | CV7: 0 | CW7: 0 | CX7: 0 | CY7: 1 | CZ7: 0 | DA7: 0 | DB7: 1 | DC7: 3 | DD7: 0 | DE7: 0 | DF7: 0 | DG7: 19 | DH7: 0 | DI7: 2 | DJ7: 0 | DK7: 0 | DL7: 0 | DM7: 0 | DN7: 1 | DO7: 0 | DP7: 2 | DQ7: 0 | DR7: 0 | DS7: 9 | DT7: 0 | DU7: 0 | DV7: 0 | DW7: 0 | DX7: 27 | DY7: 9 | DZ7: 0 | EA7: 0 | EB7: 0 | EC7: 0 | ED7: 0 | EE7: 0 | EF7: 0 | EG7: 0 | EH7: 0 | EI7: 0 | EJ7: 1 | EK7: 0 | EL7: 0 | EM7: 2 | EN7: 1 | EO7: 0 | EP7: 0 | EQ7: 0 | ER7: 0 | ES7: 0 | ET7: 0 | EU7: 0 | EV7: 0 | EW7: 0 | EX7: 0 | EY7: 0 | EZ7: 0 | FA7: 0 | FB7: 0 | FC7: 1 | FD7: 0 | FE7: 0 | FF7: 0 | FG7: 0 | FH7: 0 | FI7: 0 | FJ7: 0 | FK7: 1 | FL7: 0 | FM7: 289 | FN7: 0 | FO7: 0 | FP7: 0 | FQ7: 0 | FR7: 0 | FS7: 0 | FT7: 0 | FU7: 39 | FV7: 0 | FW7: 0 | FX7: 0 | FY7: 0 | FZ7: 0 | GA7: 1 | GB7: 0 | GC7: 9 | GD7: 0 | GE7: 1 | GF7: 0 | GG7: 5 | GH7: 1 | GI7: 0 | GJ7: 0 | GK7: 0 | GL7: 0 | GM7: 0 | GN7: 0 | GO7: 0 | GP7: 0 | GQ7: 2 | GR7: 0 | GS7: 0 | GT7: 0 | GU7: 0 | GV7: 0 | GW7: 0 | GX7: 698 | GY7: 0 | GZ7: 1 | HA7: 0 | HB7: 0 | HC7: 1 | HD7: 0 | HE7: 0 | HF7: 0 | HG7: 0 | HH7: 11 | HI7: 0 | HJ7: 0 | HK7: 0 | HL7: 1 | HM7: 0 | HN7: 0 | HO7: 0 | HP7: 0 | HQ7: 0 | HR7: 1 | HS7: 0 | HT7: 0 | HU7: 0 | HV7: 0 | HW7: 0 | HX7: 0 | HY7: 15 | HZ7: 0 | IA7: 625 | IB7: 34 | IC7: 0 | ID7: 0 | IE7: 0 | IF7: 0 | IG7: 0 | IH7: 0 | II7: 0 | IJ7: 0 | IK7: 0 | IL7: 0 | IM7: 0 | IN7: 0 | IO7: 0 | IP7: 0 | IQ7: 0 | IR7: 1 | IS7: 41 | IT7: 0 | IU7: 2 | IV7: 0 | IW7: 0 | IX7: 0 | IY7: 0 | IZ7: 0 | JA7: 0 | JB7: 0 | JC7: 0 | JD7: 0 | JE7: 1 | JF7: 2 | JG7: 0 | JH7: 0 | JI7: 0 | JJ7: 0 | JK7: 0 | JL7: 2 | JM7: 1 | JN7: 0 | JO7: 0 | JP7: 1 | JQ7: 0 | JR7: 8 | JS7: 0 | JT7: 0 | JU7: 0 | JV7: 0 | JW7: 0 | JX7: 0 | JY7: 0 | JZ7: 0 | KA7: 0 | KB7: 0 | KC7: 0 | KD7: 0 | KE7: 3 | KF7: 6 | KG7: 10 | KH7: 16 | KI7: 0 | KJ7: 2 | KK7: 0 | KL7: 12 | KM7: 0 | KN7: 0 | KO7: 0 | KP7: 11 | KQ7: 2 | KR7: 19 | KS7: 0 | KT7: 3 | KU7: 0 | KV7: 0 | KW7: 0 | KX7: 0 | KY7: 0 | KZ7: 0 | LA7: 0 | LB7: 5 | LC7: 0 | LD7: 0 | LE7: 3 | LF7: 0 | LG7: 1 | LH7: 0 | LI7: 0 | LJ7: 0 | LK7: 0 | LL7: 17 | LM7: 17 | LN7: 0 | LO7: 0 | LP7: 0 | LQ7: 0 | LR7: 0
A8: NE-BRATA-INF03 | B8: 1789 | C8: 33 | D8: 68 | E8: 1 | F8: 18 | G8: 0 | H8: 0 | I8: 0 | J8: 1 | K8: 2 | L8: 0 | M8: 4 | N8: 0 | O8: 0 | P8: 9 | Q8: 0 | R8: 0 | S8: 3 | T8: 0 | U8: 0 | V8: 0 | W8: 6 | X8: 0 | Y8: 0 | Z8: 0 | AA8: 1 | AB8: 0 | AC8: 0 | AD8: 6 | AE8: 0 | AF8: 12 | AG8: 0 | AH8: 0 | AI8: 0 | AJ8: 0 | AK8: 0 | AL8: 7 | AM8: 0 | AN8: 55 | AO8: 6 | AP8: 1 | AQ8: 0 | AR8: 0 | AS8: 0 | AT8: 0 | AU8: 0 | AV8: 15 | AW8: 0 | AX8: 20 | AY8: 0 | AZ8: 0 | BA8: 0 | BB8: 2 | BC8: 1 | BD8: 191 | BE8: 0 | BF8: 0 | BG8: 22 | BH8: 0 | BI8: 0 | BJ8: 0 | BK8: 7 | BL8: 3 | BM8: 0 | BN8: 677 | BO8: 0 | BP8: 0 | BQ8: 0 | BR8: 7 | BS8: 140 | BT8: 0 | BU8: 0 | BV8: 0 | BW8: 729 | BX8: 0 | BY8: 4 | BZ8: 7 | CA8: 0 | CB8: 84 | CC8: 2 | CD8: 0 | CE8: 0 | CF8: 4 | CG8: 0 | CH8: 0 | CI8: 0 | CJ8: 4 | CK8: 0 | CL8: 7 | CM8: 0 | CN8: 19 | CO8: 0 | CP8: 0 | CQ8: 5 | CR8: 0 | CS8: 0 | CT8: 0 | CU8: 0 | CV8: 0 | CW8: 0 | CX8: 0 | CY8: 37 | CZ8: 0 | DA8: 1 | DB8: 54 | DC8: 0 | DD8: 0 | DE8: 0 | DF8: 1 | DG8: 0 | DH8: 0 | DI8: 0 | DJ8: 0 | DK8: 13 | DL8: 0 | DM8: 0 | DN8: 0 | DO8: 0 | DP8: 2 | DQ8: 0 | DR8: 0 | DS8: 7 | DT8: 0 | DU8: 0 | DV8: 0 | DW8: 0 | DX8: 0 | DY8: 2 | DZ8: 0 | EA8: 0 | EB8: 0 | EC8: 0 | ED8: 2 | EE8: 0 | EF8: 2 | EG8: 5 | EH8: 5 | EI8: 0 | EJ8: 18 | EK8: 0 | EL8: 0 | EM8: 3 | EN8: 3 | EO8: 0 | EP8: 0 | EQ8: 0 | ER8: 0 | ES8: 2 | ET8: 0 | EU8: 0 | EV8: 0 | EW8: 0 | EX8: 0 | EY8: 0 | EZ8: 0 | FA8: 461 | FB8: 0 | FC8: 29 | FD8: 11 | FE8: 10 | FF8: 0 | FG8: 0 | FH8: 0 | FI8: 0 | FJ8: 24 | FK8: 1 | FL8: 46 | FM8: 0 | FN8: 0 | FO8: 0 | FP8: 10 | FQ8: 2 | FR8: 4 | FS8: 0 | FT8: 0 | FU8: 0 | FV8: 0 | FW8: 0 | FX8: 2 | FY8: 0 | FZ8: 0 | GA8: 0 | GB8: 0 | GC8: 27 | GD8: 4 | GE8: 0 | GF8: 8 | GG8: 0 | GH8: 0 | GI8: 0 | GJ8: 5 | GK8: 0 | GL8: 0 | GM8: 4 | GN8: 0 | GO8: 0 | GP8: 24 | GQ8: 1 | GR8: 0 | GS8: 0 | GT8: 0 | GU8: 1 | GV8: 2 | GW8: 0 | GX8: 0 | GY8: 0 | GZ8: 28 | HA8: 0 | HB8: 0 | HC8: 50 | HD8: 21 | HE8: 10 | HF8: 0 | HG8: 0 | HH8: 0 | HI8: 0 | HJ8: 11 | HK8: 0 | HL8: 27 | HM8: 0 | HN8: 0 | HO8: 0 | HP8: 0 | HQ8: 0 | HR8: 0 | HS8: 10 | HT8: 1 | HU8: 0 | HV8: 0 | HW8: 0 | HX8: 0 | HY8: 0 | HZ8: 0 | IA8: 0 | IB8: 475 | IC8: 0 | ID8: 0 | IE8: 0 | IF8: 0 | IG8: 0 | IH8: 0 | II8: 0 | IJ8: 8 | IK8: 1 | IL8: 0 | IM8: 0 | IN8: 0 | IO8: 3 | IP8: 0 | IQ8: 0 | IR8: 1 | IS8: 422 | IT8: 9 | IU8: 70 | IV8: 0 | IW8: 0 | IX8: 0 | IY8: 0 | IZ8: 0 | JA8: 0 | JB8: 0 | JC8: 0 | JD8: 0 | JE8: 0 | JF8: 0 | JG8: 0 | JH8: 0 | JI8: 0 | JJ8: 0 | JK8: 0 | JL8: 221 | JM8: 0 | JN8: 12 | JO8: 0 | JP8: 2 | JQ8: 0 | JR8: 13 | JS8: 0 | JT8: 0 | JU8: 0 | JV8: 2 | JW8: 34 | JX8: 0 | JY8: 2 | JZ8: 0 | KA8: 0 | KB8: 0 | KC8: 0 | KD8: 0 | KE8: 1 | KF8: 287 | KG8: 9 | KH8: 4 | KI8: 9 | KJ8: 0 | KK8: 0 | KL8: 0 | KM8: 1 | KN8: 0 | KO8: 0 | KP8: 0 | KQ8: 0 | KR8: 0 | KS8: 0 | KT8: 108 | KU8: 0 | KV8: 0 | KW8: 0 | KX8: 0 | KY8: 1 | KZ8: 0 | LA8: 0 | LB8: 0 | LC8: 0 | LD8: 0 | LE8: 154 | LF8: 0 | LG8: 5 | LH8: 0 | LI8: 1 | LJ8: 0 | LK8: 0 | LL8: 0 | LM8: 2 | LN8: 0 | LO8: 0 | LP8: 19 | LQ8: 0 | LR8: 1
A9: NE-BRATA-OUT04 | B9: 0 | C9: 96 | D9: 25 | E9: 663 | F9: 3 | G9: 0 | H9: 0 | I9: 0 | J9: 0 | K9: 3 | L9: 0 | M9: 6 | N9: 0 | O9: 0 | P9: 6 | Q9: 0 | R9: 2 | S9: 0 | T9: 0 | U9: 0 | V9: 0 | W9: 0 | X9: 0 | Y9: 0 | Z9: 0 | AA9: 1 | AB9: 0 | AC9: 5 | AD9: 2 | AE9: 0 | AF9: 0 | AG9: 0 | AH9: 0 | AI9: 0 | AJ9: 0 | AK9: 0 | AL9: 50 | AM9: 0 | AN9: 3 | AO9: 1 | AP9: 0 | AQ9: 0 | AR9: 0 | AS9: 1 | AT9: 0 | AU9: 0 | AV9: 0 | AW9: 1 | AX9: 0 | AY9: 4 | AZ9: 0 | BA9: 0 | BB9: 0 | BC9: 0 | BD9: 0 | BE9: 3 | BF9: 24 | BG9: 1 | BH9: 1 | BI9: 3 | BJ9: 0 | BK9: 0 | BL9: 0 | BM9: 0 | BN9: 6560 | BO9: 0 | BP9: 0 | BQ9: 0 | BR9: 0 | BS9: 0 | BT9: 4 | BU9: 1 | BV9: 0 | BW9: 0 | BX9: 0 | BY9: 152 | BZ9: 5 | CA9: 0 | CB9: 0 | CC9: 0 | CD9: 0 | CE9: 0 | CF9: 0 | CG9: 3 | CH9: 0 | CI9: 0 | CJ9: 0 | CK9: 0 | CL9: 4 | CM9: 0 | CN9: 176 | CO9: 0 | CP9: 0 | CQ9: 0 | CR9: 0 | CS9: 0 | CT9: 0 | CU9: 0 | CV9: 0 | CW9: 0 | CX9: 1 | CY9: 0 | CZ9: 0 | DA9: 0 | DB9: 0 | DC9: 0 | DD9: 0 | DE9: 0 | DF9: 0 | DG9: 0 | DH9: 0 | DI9: 0 | DJ9: 1 | DK9: 0 | DL9: 0 | DM9: 0 | DN9: 129 | DO9: 0 | DP9: 0 | DQ9: 0 | DR9: 0 | DS9: 1 | DT9: 2 | DU9: 0 | DV9: 0 | DW9: 0 | DX9: 39 | DY9: 28 | DZ9: 0 | EA9: 0 | EB9: 0 | EC9: 0 | ED9: 10 | EE9: 16 | EF9: 14 | EG9: 0 | EH9: 0 | EI9: 1 | EJ9: 0 | EK9: 1 | EL9: 0 | EM9: 35 | EN9: 0 | EO9: 2 | EP9: 0 | EQ9: 0 | ER9: 0 | ES9: 3 | ET9: 0 | EU9: 0 | EV9: 0 | EW9: 0 | EX9: 0 | EY9: 0 | EZ9: 0 | FA9: 131 | FB9: 0 | FC9: 4 | FD9: 0 | FE9: 0 | FF9: 0 | FG9: 0 | FH9: 0 | FI9: 0 | FJ9: 8 | FK9: 0 | FL9: 14 | FM9: 578 | FN9: 12 | FO9: 0 | FP9: 0 | FQ9: 0 | FR9: 0 | FS9: 0 | FT9: 0 | FU9: 0 | FV9: 0 | FW9: 0 | FX9: 0 | FY9: 0 | FZ9: 0 | GA9: 0 | GB9: 0 | GC9: 31 | GD9: 2 | GE9: 0 | GF9: 0 | GG9: 0 | GH9: 0 | GI9: 0 | GJ9: 8 | GK9: 0 | GL9: 0 | GM9: 47 | GN9: 0 | GO9: 0 | GP9: 0 | GQ9: 1 | GR9: 0 | GS9: 0 | GT9: 1 | GU9: 0 | GV9: 0 | GW9: 0 | GX9: 0 | GY9: 0 | GZ9: 2 | HA9: 0 | HB9: 0 | HC9: 2 | HD9: 11 | HE9: 2 | HF9: 4 | HG9: 0 | HH9: 4 | HI9: 0 | HJ9: 0 | HK9: 0 | HL9: 0 | HM9: 0 | HN9: 0 | HO9: 0 | HP9: 0 | HQ9: 0 | HR9: 0 | HS9: 2 | HT9: 0 | HU9: 0 | HV9: 0 | HW9: 0 | HX9: 0 | HY9: 0 | HZ9: 1 | IA9: 12 | IB9: 132 | IC9: 5 | ID9: 0 | IE9: 0 | IF9: 0 | IG9: 0 | IH9: 0 | II9: 13 | IJ9: 11 | IK9: 0 | IL9: 0 | IM9: 16 | IN9: 0 | IO9: 2 | IP9: 0 | IQ9: 0 | IR9: 0 | IS9: 4 | IT9: 175 | IU9: 1 | IV9: 0 | IW9: 0 | IX9: 0 | IY9: 0 | IZ9: 64 | JA9: 0 | JB9: 3 | JC9: 1 | JD9: 0 | JE9: 0 | JF9: 0 | JG9: 0 | JH9: 8 | JI9: 0 | JJ9: 0 | JK9: 0 | JL9: 35 | JM9: 0 | JN9: 0 | JO9: 0 | JP9: 1 | JQ9: 0 | JR9: 21 | JS9: 0 | JT9: 0 | JU9: 0 | JV9: 0 | JW9: 0 | JX9: 0 | JY9: 0 | JZ9: 364 | KA9: 0 | KB9: 0 | KC9: 11 | KD9: 1 | KE9: 4 | KF9: 0 | KG9: 71 | KH9: 0 | KI9: 5 | KJ9: 189 | KK9: 0 | KL9: 5 | KM9: 0 | KN9: 0 | KO9: 0 | KP9: 71 | KQ9: 335 | KR9: 2 | KS9: 0 | KT9: 2 | KU9: 0 | KV9: 0 | KW9: 0 | KX9: 0 | KY9: 0 | KZ9: 0 | LA9: 0 | LB9: 0 | LC9: 0 | LD9: 0 | LE9: 0 | LF9: 0 | LG9: 12 | LH9: 0 | LI9: 0 | LJ9: 0 | LK9: 0 | LL9: 0 | LM9: 0 | LN9: 0 | LO9: 0 | LP9: 1 | LQ9: 0 | LR9: 0
A10: NE-BRATA-SED05 | B10: 208734 | C10: 917 | D10: 0 | E10: 497 | F10: 1 | G10: 26 | H10: 24 | I10: 0 | J10: 8 | K10: 0 | L10: 1 | M10: 0 | N10: 126 | O10: 0 | P10: 852 | Q10: 0 | R10: 59 | S10: 99 | T10: 19 | U10: 0 | V10: 11 | W10: 171 | X10: 0 | Y10: 0 | Z10: 1 | AA10: 10 | AB10: 0 | AC10: 0 | AD10: 1 | AE10: 38 | AF10: 0 | AG10: 0 | AH10: 1 | AI10: 0 | AJ10: 0 | AK10: 0 | AL10: 0 | AM10: 0 | AN10: 0 | AO10: 0 | AP10: 0 | AQ10: 0 | AR10: 0 | AS10: 1 | AT10: 0 | AU10: 0 | AV10: 9 | AW10: 0 | AX10: 0 | AY10: 1756 | AZ10: 3 | BA10: 1 | BB10: 0 | BC10: 5 | BD10: 0 | BE10: 0 | BF10: 0 | BG10: 0 | BH10: 20 | BI10: 62 | BJ10: 0 | BK10: 0 | BL10: 0 | BM10: 1 | BN10: 31 | BO10: 0 | BP10: 0 | BQ10: 0 | BR10: 0 | BS10: 0 | BT10: 0 | BU10: 3 | BV10: 0 | BW10: 247 | BX10: 0 | BY10: 1 | BZ10: 0 | CA10: 0 | CB10: 1 | CC10: 25 | CD10: 0 | CE10: 0 | CF10: 2 | CG10: 6 | CH10: 0 | CI10: 0 | CJ10: 0 | CK10: 0 | CL10: 41 | CM10: 0 | CN10: 44 | CO10: 20 | CP10: 0 | CQ10: 0 | CR10: 0 | CS10: 53 | CT10: 0 | CU10: 2 | CV10: 0 | CW10: 0 | CX10: 0 | CY10: 0 | CZ10: 0 | DA10: 0 | DB10: 0 | DC10: 7 | DD10: 1 | DE10: 0 | DF10: 1 | DG10: 6 | DH10: 0 | DI10: 7 | DJ10: 4 | DK10: 217 | DL10: 0 | DM10: 0 | DN10: 0 | DO10: 0 | DP10: 174 | DQ10: 0 | DR10: 5 | DS10: 20 | DT10: 1 | DU10: 1 | DV10: 0 | DW10: 0 | DX10: 0 | DY10: 90 | DZ10: 0 | EA10: 6 | EB10: 0 | EC10: 1 | ED10: 15 | EE10: 251 | EF10: 1 | EG10: 0 | EH10: 0 | EI10: 0 | EJ10: 1 | EK10: 88 | EL10: 0 | EM10: 1 | EN10: 1 | EO10: 52 | EP10: 4799 | EQ10: 0 | ER10: 0 | ES10: 3 | ET10: 0 | EU10: 0 | EV10: 0 | EW10: 0 | EX10: 0 | EY10: 0 | EZ10: 0 | FA10: 1462 | FB10: 0 | FC10: 331 | FD10: 18 | FE10: 1 | FF10: 0 | FG10: 0 | FH10: 0 | FI10: 0 | FJ10: 0 | FK10: 0 | FL10: 265 | FM10: 550 | FN10: 1 | FO10: 3 | FP10: 1 | FQ10: 0 | FR10: 0 | FS10: 1 | FT10: 0 | FU10: 27 | FV10: 5 | FW10: 36 | FX10: 0 | FY10: 37 | FZ10: 0 | GA10: 1 | GB10: 0 | GC10: 0 | GD10: 40 | GE10: 825 | GF10: 9 | GG10: 4 | GH10: 0 | GI10: 0 | GJ10: 9 | GK10: 37 | GL10: 0 | GM10: 0 | GN10: 111 | GO10: 0 | GP10: 60 | GQ10: 0 | GR10: 0 | GS10: 0 | GT10: 0 | GU10: 0 | GV10: 2 | GW10: 0 | GX10: 201 | GY10: 0 | GZ10: 0 | HA10: 0 | HB10: 0 | HC10: 20 | HD10: 1880 | HE10: 0 | HF10: 1 | HG10: 0 | HH10: 0 | HI10: 20 | HJ10: 18 | HK10: 0 | HL10: 737 | HM10: 0 | HN10: 0 | HO10: 0 | HP10: 1 | HQ10: 0 | HR10: 4 | HS10: 32 | HT10: 4 | HU10: 0 | HV10: 233 | HW10: 0 | HX10: 0 | HY10: 2 | HZ10: 0 | IA10: 0 | IB10: 1246 | IC10: 10 | ID10: 0 | IE10: 0 | IF10: 0 | IG10: 1 | IH10: 0 | II10: 0 | IJ10: 30 | IK10: 3 | IL10: 0 | IM10: 153 | IN10: 0 | IO10: 0 | IP10: 0 | IQ10: 0 | IR10: 1 | IS10: 72 | IT10: 256 | IU10: 6 | IV10: 0 | IW10: 1 | IX10: 0 | IY10: 0 | IZ10: 4 | JA10: 0 | JB10: 5 | JC10: 0 | JD10: 0 | JE10: 0 | JF10: 0 | JG10: 6 | JH10: 0 | JI10: 0 | JJ10: 0 | JK10: 0 | JL10: 158 | JM10: 10 | JN10: 0 | JO10: 0 | JP10: 9 | JQ10: 0 | JR10: 1 | JS10: 0 | JT10: 0 | JU10: 0 | JV10: 13 | JW10: 4 | JX10: 0 | JY10: 122 | JZ10: 41 | KA10: 20 | KB10: 0 | KC10: 20 | KD10: 0 | KE10: 0 | KF10: 122 | KG10: 2 | KH10: 19 | KI10: 82 | KJ10: 0 | KK10: 0 | KL10: 0 | KM10: 153 | KN10: 23 | KO10: 0 | KP10: 0 | KQ10: 8 | KR10: 0 | KS10: 0 | KT10: 2 | KU10: 0 | KV10: 0 | KW10: 0 | KX10: 0 | KY10: 5 | KZ10: 0 | LA10: 1 | LB10: 0 | LC10: 1 | LD10: 0 | LE10: 37 | LF10: 5 | LG10: 159 | LH10: 0 | LI10: 11 | LJ10: 0 | LK10: 0 | LL10: 3 | LM10: 30 | LN10: 0 | LO10: 0 | LP10: 0 | LQ10: 0 | LR10: 72
A11: MD-COLRE-LIT01 | B11: 5 | C11: 7 | D11: 350 | E11: 162 | F11: 0 | G11: 0 | H11: 0 | I11: 0 | J11: 4 | K11: 4 | L11: 0 | M11: 0 | N11: 0 | O11: 0 | P11: 6 | Q11: 1 | R11: 27 | S11: 0 | T11: 0 | U11: 0 | V11: 1 | W11: 40 | X11: 0 | Y11: 0 | Z11: 0 | AA11: 0 | AB11: 0 | AC11: 0 | AD11: 0 | AE11: 0 | AF11: 6 | AG11: 0 | AH11: 4 | AI11: 1 | AJ11: 0 | AK11: 0 | AL11: 0 | AM11: 177 | AN11: 0 | AO11: 76 | AP11: 15 | AQ11: 0 | AR11: 0 | AS11: 24 | AT11: 0 | AU11: 103 | AV11: 0 | AW11: 0 | AX11: 0 | AY11: 1 | AZ11: 0 | BA11: 8 | BB11: 0 | BC11: 3 | BD11: 0 | BE11: 0 | BF11: 0 | BG11: 0 | BH11: 1 | BI11: 22 | BJ11: 3 | BK11: 0 | BL11: 13 | BM11: 0 | BN11: 33 | BO11: 0 | BP11: 1 | BQ11: 0 | BR11: 76 | BS11: 0 | BT11: 9 | BU11: 0 | BV11: 1 | BW11: 0 | BX11: 3 | BY11: 3 | BZ11: 0 | CA11: 0 | CB11: 1 | CC11: 166 | CD11: 0 | CE11: 0 | CF11: 0 | CG11: 19 | CH11: 11 | CI11: 0 | CJ11: 6 | CK11: 0 | CL11: 0 | CM11: 0 | CN11: 7 | CO11: 0 | CP11: 19 | CQ11: 0 | CR11: 1 | CS11: 0 | CT11: 1 | CU11: 18 | CV11: 42 | CW11: 0 | CX11: 0 | CY11: 11 | CZ11: 0 | DA11: 182 | DB11: 28 | DC11: 10 | DD11: 6 | DE11: 16 | DF11: 6 | DG11: 4 | DH11: 0 | DI11: 1 | DJ11: 3 | DK11: 7 | DL11: 0 | DM11: 0 | DN11: 0 | DO11: 2 | DP11: 1 | DQ11: 0 | DR11: 0 | DS11: 0 | DT11: 0 | DU11: 0 | DV11: 0 | DW11: 0 | DX11: 100 | DY11: 2 | DZ11: 0 | EA11: 1 | EB11: 0 | EC11: 1 | ED11: 1 | EE11: 8 | EF11: 0 | EG11: 0 | EH11: 0 | EI11: 2 | EJ11: 0 | EK11: 7 | EL11: 0 | EM11: 0 | EN11: 315 | EO11: 8 | EP11: 0 | EQ11: 5 | ER11: 0 | ES11: 0 | ET11: 0 | EU11: 0 | EV11: 20 | EW11: 0 | EX11: 0 | EY11: 2 | EZ11: 23 | FA11: 14 | FB11: 0 | FC11: 0 | FD11: 48 | FE11: 19 | FF11: 0 | FG11: 11 | FH11: 0 | FI11: 0 | FJ11: 1 | FK11: 0 | FL11: 351 | FM11: 824 | FN11: 0 | FO11: 0 | FP11: 0 | FQ11: 22 | FR11: 30 | FS11: 0 | FT11: 0 | FU11: 0 | FV11: 9 | FW11: 0 | FX11: 0 | FY11: 0 | FZ11: 0 | GA11: 0 | GB11: 0 | GC11: 0 | GD11: 0 | GE11: 3 | GF11: 13 | GG11: 0 | GH11: 5 | GI11: 0 | GJ11: 288 | GK11: 0 | GL11: 0 | GM11: 0 | GN11: 0 | GO11: 0 | GP11: 0 | GQ11: 149 | GR11: 2 | GS11: 0 | GT11: 0 | GU11: 0 | GV11: 0 | GW11: 12 | GX11: 0 | GY11: 0 | GZ11: 0 | HA11: 0 | HB11: 2 | HC11: 2 | HD11: 0 | HE11: 0 | HF11: 1 | HG11: 0 | HH11: 0 | HI11: 0 | HJ11: 0 | HK11: 0 | HL11: 0 | HM11: 0 | HN11: 1 | HO11: 0 | HP11: 64 | HQ11: 1 | HR11: 0 | HS11: 0 | HT11: 0 | HU11: 0 | HV11: 2 | HW11: 13 | HX11: 0 | HY11: 0 | HZ11: 1 | IA11: 146 | IB11: 177 | IC11: 2 | ID11: 0 | IE11: 0 | IF11: 0 | IG11: 0 | IH11: 0 | II11: 0 | IJ11: 14 | IK11: 0 | IL11: 0 | IM11: 64 | IN11: 0 | IO11: 0 | IP11: 0 | IQ11: 0 | IR11: 9 | IS11: 1 | IT11: 0 | IU11: 750 | IV11: 0 | IW11: 12 | IX11: 1 | IY11: 0 | IZ11: 6 | JA11: 0 | JB11: 6 | JC11: 0 | JD11: 0 | JE11: 3 | JF11: 8 | JG11: 3 | JH11: 0 | JI11: 0 | JJ11: 0 | JK11: 0 | JL11: 2 | JM11: 0 | JN11: 0 | JO11: 7 | JP11: 3 | JQ11: 0 | JR11: 0 | JS11: 3 | JT11: 0 | JU11: 0 | JV11: 15 | JW11: 55 | JX11: 0 | JY11: 0 | JZ11: 15 | KA11: 0 | KB11: 0 | KC11: 200 | KD11: 0 | KE11: 7 | KF11: 0 | KG11: 7 | KH11: 0 | KI11: 65 | KJ11: 65 | KK11: 0 | KL11: 0 | KM11: 0 | KN11: 0 | KO11: 13 | KP11: 3 | KQ11: 0 | KR11: 0 | KS11: 0 | KT11: 0 | KU11: 0 | KV11: 0 | KW11: 0 | KX11: 2 | KY11: 0 | KZ11: 1 | LA11: 1 | LB11: 0 | LC11: 23 | LD11: 0 | LE11: 0 | LF11: 2 | LG11: 0 | LH11: 0 | LI11: 12 | LJ11: 0 | LK11: 3 | LL11: 7 | LM11: 0 | LN11: 8 | LO11: 0 | LP11: 5 | LQ11: 0 | LR11: 0
A12: MD-COLRE-PEL02 | B12: 249 | C12: 1084 | D12: 186 | E12: 13 | F12: 0 | G12: 2 | H12: 4 | I12: 0 | J12: 0 | K12: 1 | L12: 0 | M12: 0 | N12: 0 | O12: 0 | P12: 1 | Q12: 26 | R12: 1 | S12: 0 | T12: 0 | U12: 0 | V12: 0 | W12: 0 | X12: 0 | Y12: 2 | Z12: 0 | AA12: 7 | AB12: 0 | AC12: 0 | AD12: 0 | AE12: 19 | AF12: 0 | AG12: 0 | AH12: 0 | AI12: 0 | AJ12: 18 | AK12: 0 | AL12: 65 | AM12: 0 | AN12: 42 | AO12: 0 | AP12: 1 | AQ12: 0 | AR12: 0 | AS12: 0 | AT12: 0 | AU12: 7 | AV12: 0 | AW12: 0 | AX12: 0 | AY12: 26 | AZ12: 0 | BA12: 1 | BB12: 0 | BC12: 1 | BD12: 2 | BE12: 5 | BF12: 0 | BG12: 0 | BH12: 300 | BI12: 5 | BJ12: 2 | BK12: 0 | BL12: 0 | BM12: 4 | BN12: 0 | BO12: 0 | BP12: 0 | BQ12: 0 | BR12: 209 | BS12: 1 | BT12: 0 | BU12: 5 | BV12: 0 | BW12: 0 | BX12: 0 | BY12: 0 | BZ12: 0 | CA12: 0 | CB12: 4 | CC12: 38 | CD12: 0 | CE12: 2 | CF12: 0 | CG12: 115 | CH12: 4 | CI12: 0 | CJ12: 0 | CK12: 0 | CL12: 17 | CM12: 0 | CN12: 1 | CO12: 0 | CP12: 0 | CQ12: 0 | CR12: 1 | CS12: 12 | CT12: 0 | CU12: 24 | CV12: 0 | CW12: 0 | CX12: 7 | CY12: 2 | CZ12: 0 | DA12: 147 | DB12: 2 | DC12: 0 | DD12: 0 | DE12: 0 | DF12: 0 | DG12: 39 | DH12: 0 | DI12: 340 | DJ12: 2 | DK12: 12 | DL12: 0 | DM12: 0 | DN12: 35 | DO12: 17 | DP12: 0 | DQ12: 0 | DR12: 0 | DS12: 4 | DT12: 0 | DU12: 0 | DV12: 0 | DW12: 0 | DX12: 0 | DY12: 9 | DZ12: 0 | EA12: 0 | EB12: 0 | EC12: 3 | ED12: 0 | EE12: 0 | EF12: 0 | EG12: 1 | EH12: 3 | EI12: 9 | EJ12: 0 | EK12: 6 | EL12: 0 | EM12: 0 | EN12: 87 | EO12: 15 | EP12: 0 | EQ12: 0 | ER12: 9 | ES12: 0 | ET12: 0 | EU12: 0 | EV12: 0 | EW12: 0 | EX12: 3 | EY12: 2 | EZ12: 3 | FA12: 132 | FB12: 1 | FC12: 0 | FD12: 241 | FE12: 9 | FF12: 4 | FG12: 0 | FH12: 0 | FI12: 0 | FJ12: 13 | FK12: 3 | FL12: 11001 | FM12: 0 | FN12: 0 | FO12: 3 | FP12: 0 | FQ12: 0 | FR12: 0 | FS12: 0 | FT12: 0 | FU12: 0 | FV12: 2 | FW12: 1 | FX12: 178 | FY12: 0 | FZ12: 0 | GA12: 5 | GB12: 0 | GC12: 0 | GD12: 0 | GE12: 0 | GF12: 37 | GG12: 0 | GH12: 0 | GI12: 0 | GJ12: 4 | GK12: 0 | GL12: 1 | GM12: 13 | GN12: 0 | GO12: 24 | GP12: 1107 | GQ12: 0 | GR12: 0 | GS12: 0 | GT12: 0 | GU12: 0 | GV12: 92 | GW12: 0 | GX12: 1 | GY12: 0 | GZ12: 0 | HA12: 0 | HB12: 1 | HC12: 17 | HD12: 0 | HE12: 0 | HF12: 3 | HG12: 5 | HH12: 0 | HI12: 42 | HJ12: 0 | HK12: 0 | HL12: 0 | HM12: 6 | HN12: 1 | HO12: 4 | HP12: 0 | HQ12: 0 | HR12: 0 | HS12: 0 | HT12: 0 | HU12: 0 | HV12: 3 | HW12: 340 | HX12: 40 | HY12: 431 | HZ12: 0 | IA12: 3271 | IB12: 0 | IC12: 0 | ID12: 0 | IE12: 0 | IF12: 0 | IG12: 0 | IH12: 0 | II12: 0 | IJ12: 2 | IK12: 0 | IL12: 0 | IM12: 0 | IN12: 1 | IO12: 0 | IP12: 15 | IQ12: 0 | IR12: 1 | IS12: 1 | IT12: 5 | IU12: 0 | IV12: 0 | IW12: 7 | IX12: 0 | IY12: 0 | IZ12: 0 | JA12: 2 | JB12: 0 | JC12: 0 | JD12: 0 | JE12: 4 | JF12: 0 | JG12: 0 | JH12: 0 | JI12: 0 | JJ12: 0 | JK12: 0 | JL12: 7 | JM12: 0 | JN12: 0 | JO12: 0 | JP12: 1 | JQ12: 24 | JR12: 4 | JS12: 2 | JT12: 0 | JU12: 0 | JV12: 0 | JW12: 2 | JX12: 0 | JY12: 0 | JZ12: 154 | KA12: 0 | KB12: 1 | KC12: 1 | KD12: 0 | KE12: 0 | KF12: 20 | KG12: 0 | KH12: 189 | KI12: 12 | KJ12: 25 | KK12: 0 | KL12: 1 | KM12: 0 | KN12: 0 | KO12: 2 | KP12: 0 | KQ12: 57 | KR12: 75 | KS12: 0 | KT12: 58 | KU12: 0 | KV12: 0 | KW12: 3 | KX12: 2 | KY12: 0 | KZ12: 0 | LA12: 10 | LB12: 0 | LC12: 1 | LD12: 0 | LE12: 0 | LF12: 0 | LG12: 37 | LH12: 4 | LI12: 13 | LJ12: 2 | LK12: 157 | LL12: 0 | LM12: 1 | LN12: 7 | LO12: 0 | LP12: 1 | LQ12: 0 | LR12: 2
A13: MD-COLRE-INF03 | B13: 1334 | C13: 241 | D13: 2 | E13: 0 | F13: 0 | G13: 1 | H13: 2 | I13: 0 | J13: 0 | K13: 1 | L13: 290 | M13: 6 | N13: 0 | O13: 0 | P13: 0 | Q13: 73 | R13: 0 | S13: 0 | T13: 0 | U13: 0 | V13: 5 | W13: 0 | X13: 0 | Y13: 3 | Z13: 3 | AA13: 22 | AB13: 0 | AC13: 0 | AD13: 2 | AE13: 0 | AF13: 3 | AG13: 0 | AH13: 3 | AI13: 4 | AJ13: 0 | AK13: 0 | AL13: 13 | AM13: 5 | AN13: 36 | AO13: 0 | AP13: 100 | AQ13: 8 | AR13: 153 | AS13: 35 | AT13: 0 | AU13: 54 | AV13: 0 | AW13: 0 | AX13: 6 | AY13: 1 | AZ13: 0 | BA13: 0 | BB13: 0 | BC13: 0 | BD13: 102 | BE13: 15 | BF13: 0 | BG13: 18 | BH13: 6 | BI13: 501 | BJ13: 0 | BK13: 42 | BL13: 3 | BM13: 0 | BN13: 515 | BO13: 0 | BP13: 0 | BQ13: 0 | BR13: 51 | BS13: 0 | BT13: 10 | BU13: 2 | BV13: 0 | BW13: 0 | BX13: 37 | BY13: 0 | BZ13: 0 | CA13: 0 | CB13: 3 | CC13: 660 | CD13: 1 | CE13: 1 | CF13: 27 | CG13: 3 | CH13: 0 | CI13: 2 | CJ13: 0 | CK13: 0 | CL13: 7 | CM13: 0 | CN13: 2 | CO13: 28 | CP13: 26 | CQ13: 1 | CR13: 0 | CS13: 3 | CT13: 3 | CU13: 762 | CV13: 0 | CW13: 0 | CX13: 0 | CY13: 4043 | CZ13: 5 | DA13: 2 | DB13: 0 | DC13: 0 | DD13: 633 | DE13: 167 | DF13: 3 | DG13: 25 | DH13: 0 | DI13: 0 | DJ13: 0 | DK13: 0 | DL13: 28 | DM13: 0 | DN13: 1 | DO13: 1 | DP13: 0 | DQ13: 0 | DR13: 0 | DS13: 178 | DT13: 8 | DU13: 18 | DV13: 24 | DW13: 0 | DX13: 1 | DY13: 3 | DZ13: 0 | EA13: 2 | EB13: 0 | EC13: 0 | ED13: 6 | EE13: 0 | EF13: 1 | EG13: 80 | EH13: 2 | EI13: 0 | EJ13: 0 | EK13: 6 | EL13: 0 | EM13: 33 | EN13: 0 | EO13: 12 | EP13: 0 | EQ13: 110 | ER13: 17 | ES13: 0 | ET13: 0 | EU13: 33 | EV13: 0 | EW13: 0 | EX13: 2 | EY13: 22 | EZ13: 0 | FA13: 387 | FB13: 39 | FC13: 0 | FD13: 142 | FE13: 471 | FF13: 0 | FG13: 41 | FH13: 3 | FI13: 10 | FJ13: 51 | FK13: 1 | FL13: 2839 | FM13: 75 | FN13: 0 | FO13: 0 | FP13: 0 | FQ13: 180 | FR13: 0 | FS13: 19 | FT13: 0 | FU13: 0 | FV13: 0 | FW13: 0 | FX13: 0 | FY13: 341 | FZ13: 0 | GA13: 2 | GB13: 41 | GC13: 0 | GD13: 0 | GE13: 499 | GF13: 73 | GG13: 0 | GH13: 1 | GI13: 0 | GJ13: 66 | GK13: 0 | GL13: 0 | GM13: 81 | GN13: 0 | GO13: 14 | GP13: 273 | GQ13: 75 | GR13: 2 | GS13: 0 | GT13: 3 | GU13: 0 | GV13: 10 | GW13: 261 | GX13: 0 | GY13: 0 | GZ13: 0 | HA13: 0 | HB13: 0 | HC13: 4 | HD13: 7 | HE13: 0 | HF13: 30 | HG13: 44 | HH13: 0 | HI13: 9 | HJ13: 0 | HK13: 0 | HL13: 281 | HM13: 8 | HN13: 0 | HO13: 0 | HP13: 0 | HQ13: 0 | HR13: 0 | HS13: 0 | HT13: 0 | HU13: 9 | HV13: 0 | HW13: 3620 | HX13: 0 | HY13: 23 | HZ13: 5 | IA13: 57 | IB13: 47 | IC13: 0 | ID13: 2 | IE13: 0 | IF13: 0 | IG13: 0 | IH13: 0 | II13: 0 | IJ13: 0 | IK13: 2 | IL13: 0 | IM13: 747 | IN13: 0 | IO13: 0 | IP13: 4 | IQ13: 0 | IR13: 0 | IS13: 182 | IT13: 51 | IU13: 0 | IV13: 2 | IW13: 5 | IX13: 5 | IY13: 0 | IZ13: 0 | JA13: 0 | JB13: 0 | JC13: 0 | JD13: 2 | JE13: 2 | JF13: 151 | JG13: 2 | JH13: 0 | JI13: 16 | JJ13: 0 | JK13: 0 | JL13: 3 | JM13: 0 | JN13: 0 | JO13: 0 | JP13: 17 | JQ13: 0 | JR13: 0 | JS13: 0 | JT13: 0 | JU13: 24 | JV13: 0 | JW13: 2 | JX13: 97 | JY13: 0 | JZ13: 0 | KA13: 0 | KB13: 129 | KC13: 39 | KD13: 0 | KE13: 122 | KF13: 40 | KG13: 0 | KH13: 0 | KI13: 156 | KJ13: 0 | KK13: 0 | KL13: 0 | KM13: 0 | KN13: 11 | KO13: 3 | KP13: 4 | KQ13: 4 | KR13: 0 | KS13: 0 | KT13: 125 | KU13: 2 | KV13: 4 | KW13: 1 | KX13: 0 | KY13: 11 | KZ13: 0 | LA13: 0 | LB13: 0 | LC13: 1 | LD13: 0 | LE13: 23 | LF13: 0 | LG13: 2 | LH13: 1 | LI13: 85 | LJ13: 5 | LK13: 9 | LL13: 0 | LM13: 0 | LN13: 1 | LO13: 10 | LP13: 0 | LQ13: 0 | LR13: 3
... A132: SW-TARBR-INF03 | B132: 123 | C132: 0 | D132: 204 | E132: 29 | F132: 0 | G132: 0 | H132: 0 | I132: 0 | J132: 0 | K132: 1 | L132: 0 | M132: 0 | N132: 0 | O132: 8 | P132: 0 | Q132: 0 | R132: 0 | S132: 0 | T132: 0 | U132: 0 | V132: 0 | W132: 0 | X132: 0 | Y132: 0 | Z132: 0 | AA132: 0 | AB132: 51 | AC132: 0 | AD132: 0 | AE132: 0 | AF132: 0 | AG132: 0 | AH132: 0 | AI132: 1 | AJ132: 0 | AK132: 6 | AL132: 22 | AM132: 0 | AN132: 0 | AO132: 0 | AP132: 0 | AQ132: 0 | AR132: 409 | AS132: 0 | AT132: 0 | AU132: 79 | AV132: 0 | AW132: 0 | AX132: 0 | AY132: 0 | AZ132: 0 | BA132: 4 | BB132: 0 | BC132: 0 | BD132: 3 | BE132: 3 | BF132: 0 | BG132: 0 | BH132: 0 | BI132: 9 | BJ132: 0 | BK132: 115 | BL132: 0 | BM132: 72 | BN132: 0 | BO132: 8 | BP132: 12 | BQ132: 0 | BR132: 0 | BS132: 0 | BT132: 0 | BU132: 1 | BV132: 31 | BW132: 0 | BX132: 0 | BY132: 0 | BZ132: 0 | CA132: 0 | CB132: 0 | CC132: 1 | CD132: 28 | CE132: 0 | CF132: 0 | CG132: 0 | CH132: 0 | CI132: 0 | CJ132: 0 | CK132: 0 | CL132: 0 | CM132: 0 | CN132: 0 | CO132: 2 | CP132: 88 | CQ132: 0 | CR132: 1 | CS132: 0 | CT132: 0 | CU132: 0 | CV132: 0 | CW132: 0 | CX132: 35 | CY132: 26 | CZ132: 0 | DA132: 23 | DB132: 0 | DC132: 0 | DD132: 0 | DE132: 1 | DF132: 0 | DG132: 0 | DH132: 0 | DI132: 0 | DJ132: 0 | DK132: 0 | DL132: 575 | DM132: 0 | DN132: 0 | DO132: 1 | DP132: 0 | DQ132: 20 | DR132: 1 | DS132: 3 | DT132: 0 | DU132: 0 | DV132: 0 | DW132: 0 | DX132: 0 | DY132: 0 | DZ132: 0 | EA132: 0 | EB132: 17 | EC132: 0 | ED132: 0 | EE132: 0 | EF132: 0 | EG132: 0 | EH132: 0 | EI132: 0 | EJ132: 0 | EK132: 0 | EL132: 0 | EM132: 0 | EN132: 0 | EO132: 0 | EP132: 0 | EQ132: 3 | ER132: 2 | ES132: 1 | ET132: 0 | EU132: 43 | EV132: 15 | EW132: 0 | EX132: 0 | EY132: 0 | EZ132: 0 | FA132: 3 | FB132: 73 | FC132: 2 | FD132: 0 | FE132: 0 | FF132: 0 | FG132: 0 | FH132: 0 | FI132: 1 | FJ132: 30 | FK132: 0 | FL132: 1303 | FM132: 0 | FN132: 0 | FO132: 0 | FP132: 0 | FQ132: 0 | FR132: 0 | FS132: 0 | FT132: 0 | FU132: 0 | FV132: 0 | FW132: 0 | FX132: 1 | FY132: 0 | FZ132: 0 | GA132: 0 | GB132: 0 | GC132: 0 | GD132: 0 | GE132: 15 | GF132: 0 | GG132: 0 | GH132: 0 | GI132: 0 | GJ132: 18 | GK132: 0 | GL132: 0 | GM132: 0 | GN132: 0 | GO132: 0 | GP132: 0 | GQ132: 0 | GR132: 0 | GS132: 198 | GT132: 0 | GU132: 8 | GV132: 9782 | GW132: 0 | GX132: 0 | GY132: 0 | GZ132: 0 | HA132: 36 | HB132: 8 | HC132: 0 | HD132: 0 | HE132: 0 | HF132: 0 | HG132: 3 | HH132: 0 | HI132: 0 | HJ132: 0 | HK132: 0 | HL132: 1 | HM132: 0 | HN132: 0 | HO132: 0 | HP132: 0 | HQ132: 4 | HR132: 0 | HS132: 0 | HT132: 0 | HU132: 1 | HV132: 0 | HW132: 0 | HX132: 13 | HY132: 2662 | HZ132: 0 | IA132: 3 | IB132: 2 | IC132: 0 | ID132: 0 | IE132: 96 | IF132: 22 | IG132: 0 | IH132: 8 | II132: 0 | IJ132: 0 | IK132: 0 | IL132: 9 | IM132: 1 | IN132: 125 | IO132: 0 | IP132: 0 | IQ132: 196 | IR132: 146 | IS132: 0 | IT132: 0 | IU132: 10 | IV132: 0 | IW132: 14 | IX132: 1 | IY132: 0 | IZ132: 0 | JA132: 0 | JB132: 2 | JC132: 0 | JD132: 0 | JE132: 0 | JF132: 0 | JG132: 8 | JH132: 0 | JI132: 0 | JJ132: 0 | JK132: 4 | JL132: 2 | JM132: 0 | JN132: 0 | JO132: 3 | JP132: 0 | JQ132: 0 | JR132: 0 | JS132: 62 | JT132: 2 | JU132: 1 | JV132: 0 | JW132: 0 | JX132: 27 | JY132: 0 | JZ132: 0 | KA132: 0 | KB132: 0 | KC132: 0 | KD132: 0 | KE132: 0 | KF132: 1 | KG132: 0 | KH132: 10 | KI132: 0 | KJ132: 20 | KK132: 0 | KL132: 0 | KM132: 0 | KN132: 0 | KO132: 0 | KP132: 0 | KQ132: 0 | KR132: 0 | KS132: 0 | KT132: 0 | KU132: 0 | KV132: 0 | KW132: 0 | KX132: 0 | KY132: 0 | KZ132: 0 | LA132: 0 | LB132: 0 | LC132: 0 | LD132: 0 | LE132: 0 | LF132: 0 | LG132: 62 | LH132: 0 | LI132: 0 | LJ132: 8 | LK132: 0 | LL132: 0 | LM132: 0 | LN132: 1 | LO132: 0 | LP132: 13 | LQ132: 0 | LR132: 0

Sheet occurrence
A1: Site | B1: Limnohabitans | C1: Polynucleobacter | D1: Rhodoferax | E1: Albidiferax | F1: Curvibacter | G1: Hydrogenophaga | H1: Acidovorax | I1: Comamonas | J1: Delftia | K1: Methylibium | L1: Leptothrix | M1: Sphaerotilus | N1: Aquabacterium | O1: Rubrivivax | P1: Roseateles | Q1: Pelomonas | R1: Aquincola | S1: Inhella | T1: Malikia | U1: Simplicispira | V1: Diaphorobacter | W1: Alicycliphilus | X1: Brachymonas | Y1: Giesbergeria | Z1: Rhizobacter | AA1: Piscinibacter | AB1: Thiomonas | AC1: Ramlibacter | AD1: Caenimonas | AE1: Xenophilus | AF1: Herbaspirillum | AG1: Janthinobacterium | AH1: Undibacterium | AI1: Herminiimonas | AJ1: Oxalobacter | AK1: Ralstonia | AL1: Cupriavidus | AM1: Paraburkholderia | AN1: Achromobacter | AO1: Alcaligenes | AP1: Bordetella | AQ1: Methylotenera | AR1: Methylobacillus | AS1: Methylovorus | AT1: Nitrosomonas | AU1: Nitrosospira | AV1: Thiobacillus | AW1: Sulfuricella | AX1: Gallionella | AY1: Sideroxydans | AZ1: Dechloromonas | BA1: Zoogloea | BB1: Denitratisoma | BC1: Sterolibacterium | BD1: Ferribacterium | BE1: Propionivibrio | BF1: Uliginosibacterium | BG1: Rhodocyclus | BH1: Azonexus | BI1: Methyloversatilis | BJ1: Georgfuchsia | BK1: Candidatus Accumulibacter | BL1: Candidatus Methylopumilus | BM1: Hydrogenophilus | BN1: Candidatus Fonsibacter | BO1: Novosphingobium | BP1: Sphingomonas | BQ1: Sphingobium | BR1: Sphingopyxis | BS1: Sphingorhabdus | BT1: Blastomonas | BU1: Sandarakinorhabdus | BV1: Erythrobacter | BW1: Porphyrobacter | BX1: Altererythrobacter | BY1: Caulobacter | BZ1: Brevundimonas | CA1: Phenylobacterium | CB1: Asticcacaulis | CC1: Methylobacterium | CD1: Bradyrhizobium | CE1: Rhizobium | CF1: Mesorhizobium | CG1: Agrobacterium | CH1: Shinella | CI1: Devosia | CJ1: Afipia | CK1: Rhodopseudomonas | CL1: Rhodoplanes | CM1: Pedomicrobium | CN1: Hyphomonas | CO1: Rhodobacter | CP1: Paracoccus | CQ1: Gemmobacter | CR1: Rhodobaca | CS1: Tabrizicola | CT1: Roseomonas | CU1: Acidiphilium | CV1: Methylocystis | CW1: Methylosinus | CX1: Ochrobactrum | CY1: Reyranella | CZ1: Bauldia | DA1: Rhodomicrobium | DB1: Elstera | DC1: Rhodovarius | DD1: Pseudomonas | DE1: Acinetobacter | DF1: Aeromonas | DG1: Shewanella | DH1: Rheinheimera | DI1: Stenotrophomonas | DJ1: Lysobacter | DK1: Arenimonas | DL1: Luteimonas | DM1: Pseudoxanthomonas | DN1: Xanthomonas | DO1: Rhodanobacter | DP1: Dyella | DQ1: Legionella | DR1: Methylobacter | DS1: Crenothrix | DT1: Methylocaldum | DU1: Methylosarcina | DV1: Methylovulum | DW1: Methylomicrobium | DX1: Methyloglobulus | DY1: Beggiatoa | DZ1: Thioploca | EA1: Psychrobacter | EB1: Perlucidibaca | EC1: Cellvibrio | ED1: Serratia | EE1: Rahnella | EF1: Pantoea | EG1: Klebsiella | EH1: Escherichia | EI1: Hafnia | EJ1: Nevskia | EK1: Hydrocarboniphaga | EL1: Aquicella | EM1: Alishewanella | EN1: Tolumonas | EO1: Steroidobacter | EP1: Desulfovibrio | EQ1: Desulfomicrobium | ER1: Desulfobulbus | ES1: Desulfobacca | ET1: Desulfobacterium | EU1: Desulfatirhabdium | EV1: Geobacter | EW1: Syntrophus | EX1: Syntrophobacter | EY1: Smithella | EZ1: Syntrophorhabdus | FA1: Bdellovibrio | FB1: Haliangium | FC1: Anaeromyxobacter | FD1: Myxococcus | FE1: Sorangium | FF1: Nannocystis | FG1: Polyangium | FH1: Arcobacter | FI1: Sulfurospirillum | FJ1: Sulfuricurvum | FK1: Sulfurimonas | FL1: Candidatus Planktophila | FM1: Candidatus Nanopelagicus | FN1: Rhodoluna | FO1: Aurantimicrobium | FP1: Ilumatobacter | FQ1: Iamia | FR1: Microbacterium | FS1: Agromyces | FT1: Frigoribacterium | FU1: Mycobacterium | FV1: Arthrobacter | FW1: Aeromicrobium | FX1: Marmoricola | FY1: Streptomyces | FZ1: Micrococcus | GA1: Kocuria | GB1: Rothia | GC1: Rhodococcus | GD1: Gordonia | GE1: Nocardia | GF1: Dietzia | GG1: Pseudonocardia | GH1: Amycolatopsis | GI1: Actinoplanes | GJ1: Micromonospora | GK1: Blastococcus | GL1: Geodermatophilus | GM1: Modestobacter | GN1: Frankia | GO1: Demequina | GP1: Phycicoccus | GQ1: Tetrasphaera | GR1: Janibacter | GS1: Knoellia | GT1: Conexibacter | GU1: Candidatus Microthrix | GV1: Flavobacterium | GW1: Cloacibacterium | GX1: Fluviicola | GY1: Flectobacillus | GZ1: Runella | HA1: Spirosoma | HB1: Dyadobacter | HC1: Cytophaga | HD1: Sediminibacterium | HE1: Ferruginibacter | HF1: Terrimonas | HG1: Chitinophaga | HH1: Niabella | HI1: Lacibacter | HJ1: Haliscomenobacter | HK1: Solitalea | HL1: Mucilaginibacter | HM1: Sphingobacterium | HN1: Bacteroides | HO1: Prevotella | HP1: Lentimicrobium | HQ1: Rhodonellum | HR1: Lutibacter | HS1: Aquirufa | HT1: Fibrella | HU1: Flavisolibacter | HV1: Parasediminibacterium | HW1: Microcystis | HX1: Planktothrix | HY1: Dolichospermum | HZ1: Aphanizomenon | IA1: Synechococcus | IB1: Cyanobium | IC1: Pseudanabaena | ID1: Raphidiopsis | IE1: Nostoc | IF1: Anabaena | IG1: Oscillatoria | IH1: Phormidium | II1: Snowella | IJ1: Woronichinia | IK1: Limnothrix | IL1: Planktolyngbya | IM1: Chroococcus | IN1: Aphanocapsa | IO1: Merismopedia | IP1: Tychonema | IQ1: Microseira | IR1: Luteolibacter | IS1: Prosthecobacter | IT1: Verrucomicrobium | IU1: Opitutus | IV1: Lacunisphaera | IW1: Roseimicrobium | IX1: Brevifollis | IY1: Persicirhabdus | IZ1: Terrimicrobium | JA1: Candidatus Udaeobacter | JB1: Chthoniobacter | JC1: Planctomyces | JD1: Gemmata | JE1: Pirellula | JF1: Rhodopirellula | JG1: Schlesneria | JH1: Zavarzinella | JI1: Blastopirellula | JJ1: Planctopirus | JK1: Tepidisphaera | JL1: Acidobacterium | JM1: Granulicella | JN1: Bryobacter | JO1: Candidatus Solibacter | JP1: Geothrix | JQ1: Terriglobus | JR1: Edaphobacter | JS1: Luteitalea | JT1: Vicinamibacter | JU1: Chloroflexus | JV1: Anaerolinea | JW1: Longilinea | JX1: Bellilinea | JY1: Levilinea | JZ1: Roseiflexus | KA1: Herpetosiphon | KB1: Caldilinea | KC1: Leptolinea | KD1: Ornatilinea | KE1: Litorilinea | KF1: Bacillus | KG1: Paenibacillus | KH1: Lysinibacillus | KI1: Brevibacillus | KJ1: Exiguobacterium | KK1: Planococcus | KL1: Staphylococcus | KM1: Clostridium | KN1: Turicibacter | KO1: Sporomusa | KP1: Acetobacterium | KQ1: Desulfitobacterium | KR1: Desulfosporosinus | KS1: Carnobacterium | KT1: Lactococcus | KU1: Streptococcus | KV1: Enterococcus | KW1: Faecalibacterium | KX1: Blautia | KY1: Ruminococcus | KZ1: Dorea | LA1: Lachnoclostridium | LB1: Subdoligranulum | LC1: Sedimentibacter | LD1: Christensenella | LE1: Nitrospira | LF1: Thermodesulfovibrio | LG1: Gemmatimonas | LH1: Armatimonas | LI1: Fimbriimonas | LJ1: Deinococcus | LK1: Leptospira | LL1: Treponema | LM1: Ignavibacterium | LN1: Chlorobium | LO1: Pelodictyon | LP1: Fusobacterium | LQ1: Elusimicrobium | LR1: Fibrobacter
A2: =abundance!A2 -> NW-ASHME-LIT01 | B2: =IF(abundance!B2>0,1,0) -> 1 | C2: =IF(abundance!C2>0,1,0) -> 0 | D2: =IF(abundance!D2>0,1,0) -> 1 | E2: =IF(abundance!E2>0,1,0) -> 1 | F2: =IF(abundance!F2>0,1,0) -> 0 | G2: =IF(abundance!G2>0,1,0) -> 0 | H2: =IF(abundance!H2>0,1,0) -> 0 | I2: =IF(abundance!I2>0,1,0) -> 0 | ... LR2: =IF(abundance!LR2>0,1,0) -> 0
A3: =abundance!A3 -> NW-ASHME-PEL02 | B3: =IF(abundance!B3>0,1,0) -> 0 | C3: =IF(abundance!C3>0,1,0) -> 0 | D3: =IF(abundance!D3>0,1,0) -> 1 | E3: =IF(abundance!E3>0,1,0) -> 0 | F3: =IF(abundance!F3>0,1,0) -> 0 | G3: =IF(abundance!G3>0,1,0) -> 0 | H3: =IF(abundance!H3>0,1,0) -> 0 | I3: =IF(abundance!I3>0,1,0) -> 0 | ... LR3: =IF(abundance!LR3>0,1,0) -> 0
A4: =abundance!A4 -> NW-ASHME-OUT03 | B4: =IF(abundance!B4>0,1,0) -> 1 | C4: =IF(abundance!C4>0,1,0) -> 0 | D4: =IF(abundance!D4>0,1,0) -> 1 | E4: =IF(abundance!E4>0,1,0) -> 1 | F4: =IF(abundance!F4>0,1,0) -> 0 | G4: =IF(abundance!G4>0,1,0) -> 0 | H4: =IF(abundance!H4>0,1,0) -> 1 | I4: =IF(abundance!I4>0,1,0) -> 0 | ... LR4: =IF(abundance!LR4>0,1,0) -> 0
A5: =abundance!A5 -> NW-ASHME-SED04 | B5: =IF(abundance!B5>0,1,0) -> 0 | C5: =IF(abundance!C5>0,1,0) -> 0 | D5: =IF(abundance!D5>0,1,0) -> 1 | E5: =IF(abundance!E5>0,1,0) -> 1 | F5: =IF(abundance!F5>0,1,0) -> 0 | G5: =IF(abundance!G5>0,1,0) -> 0 | H5: =IF(abundance!H5>0,1,0) -> 1 | I5: =IF(abundance!I5>0,1,0) -> 0 | ... LR5: =IF(abundance!LR5>0,1,0) -> 0
A6: =abundance!A6 -> NE-BRATA-LIT01 | B6: =IF(abundance!B6>0,1,0) -> 1 | C6: =IF(abundance!C6>0,1,0) -> 1 | D6: =IF(abundance!D6>0,1,0) -> 0 | E6: =IF(abundance!E6>0,1,0) -> 0 | F6: =IF(abundance!F6>0,1,0) -> 0 | G6: =IF(abundance!G6>0,1,0) -> 1 | H6: =IF(abundance!H6>0,1,0) -> 0 | I6: =IF(abundance!I6>0,1,0) -> 0 | ... LR6: =IF(abundance!LR6>0,1,0) -> 0
A7: =abundance!A7 -> NE-BRATA-PEL02 | B7: =IF(abundance!B7>0,1,0) -> 1 | C7: =IF(abundance!C7>0,1,0) -> 1 | D7: =IF(abundance!D7>0,1,0) -> 0 | E7: =IF(abundance!E7>0,1,0) -> 0 | F7: =IF(abundance!F7>0,1,0) -> 0 | G7: =IF(abundance!G7>0,1,0) -> 0 | H7: =IF(abundance!H7>0,1,0) -> 1 | I7: =IF(abundance!I7>0,1,0) -> 0 | ... LR7: =IF(abundance!LR7>0,1,0) -> 0
A8: =abundance!A8 -> NE-BRATA-INF03 | B8: =IF(abundance!B8>0,1,0) -> 1 | C8: =IF(abundance!C8>0,1,0) -> 1 | D8: =IF(abundance!D8>0,1,0) -> 1 | E8: =IF(abundance!E8>0,1,0) -> 1 | F8: =IF(abundance!F8>0,1,0) -> 1 | G8: =IF(abundance!G8>0,1,0) -> 0 | H8: =IF(abundance!H8>0,1,0) -> 0 | I8: =IF(abundance!I8>0,1,0) -> 0 | ... LR8: =IF(abundance!LR8>0,1,0) -> 1
A9: =abundance!A9 -> NE-BRATA-OUT04 | B9: =IF(abundance!B9>0,1,0) -> 0 | C9: =IF(abundance!C9>0,1,0) -> 1 | D9: =IF(abundance!D9>0,1,0) -> 1 | E9: =IF(abundance!E9>0,1,0) -> 1 | F9: =IF(abundance!F9>0,1,0) -> 1 | G9: =IF(abundance!G9>0,1,0) -> 0 | H9: =IF(abundance!H9>0,1,0) -> 0 | I9: =IF(abundance!I9>0,1,0) -> 0 | ... LR9: =IF(abundance!LR9>0,1,0) -> 0
A10: =abundance!A10 -> NE-BRATA-SED05 | B10: =IF(abundance!B10>0,1,0) -> 1 | C10: =IF(abundance!C10>0,1,0) -> 1 | D10: =IF(abundance!D10>0,1,0) -> 0 | E10: =IF(abundance!E10>0,1,0) -> 1 | F10: =IF(abundance!F10>0,1,0) -> 1 | G10: =IF(abundance!G10>0,1,0) -> 1 | H10: =IF(abundance!H10>0,1,0) -> 1 | I10: =IF(abundance!I10>0,1,0) -> 0 | ... LR10: =IF(abundance!LR10>0,1,0) -> 1
A11: =abundance!A11 -> MD-COLRE-LIT01 | B11: =IF(abundance!B11>0,1,0) -> 1 | C11: =IF(abundance!C11>0,1,0) -> 1 | D11: =IF(abundance!D11>0,1,0) -> 1 | E11: =IF(abundance!E11>0,1,0) -> 1 | F11: =IF(abundance!F11>0,1,0) -> 0 | G11: =IF(abundance!G11>0,1,0) -> 0 | H11: =IF(abundance!H11>0,1,0) -> 0 | I11: =IF(abundance!I11>0,1,0) -> 0 | ... LR11: =IF(abundance!LR11>0,1,0) -> 0
A12: =abundance!A12 -> MD-COLRE-PEL02 | B12: =IF(abundance!B12>0,1,0) -> 1 | C12: =IF(abundance!C12>0,1,0) -> 1 | D12: =IF(abundance!D12>0,1,0) -> 1 | E12: =IF(abundance!E12>0,1,0) -> 1 | F12: =IF(abundance!F12>0,1,0) -> 0 | G12: =IF(abundance!G12>0,1,0) -> 1 | H12: =IF(abundance!H12>0,1,0) -> 1 | I12: =IF(abundance!I12>0,1,0) -> 0 | ... LR12: =IF(abundance!LR12>0,1,0) -> 1
